Workbook

Sheet Януари
A1: Дата | B1: Смяна | C1: Диспечер | D1: Подадена руда от МГТЛ за денонощието | E1: Състояние на склад №2 | F1: Натрошена руда от Цех ССТ | G1: Класа +15,0мм. | H1: Класа +12,5мм. | I1: Превозена руда до междинни бункери | J1: Състояние на междинни бункери | K1: Преработена руда в цех МФЦ | L1: Влага на преработената руда | M1: Суха преработена руда | N1: Грано диорити | P1: Дайки | R1: Шисти | S1: Показания на Гранулометър PSI500i руда, +0,20мм | U1: Смилане класа +0,20мм | W1: Смилане класа -0,08мм | Y1: Плътност на пулпа | AA1: Съдържание на мед в рудите по Химия | AB1: Метал мед в рудите по Химия | AC1: Съдържание на мед в рудите по Куриер | AD1: Метал мед в рудите по Куриер | AE1: Коригирана съдържание на мед в рудите | AF1: Съдържание на мед в отпадъка по Куриер | AG1: Метал мед в отпадъка по Куриер | AH1: Съдържание на мед в медния к-т Куриер | AI1: Метал мед в концентрата по Куриер | AJ1: Технологично извличане по Куриер | AK1: Товарно извличане | AL1: Добит меден концентрат | AM1: Влага на медния концентрат | AN1: Съдържание на мед в медния к-т (Брукер) | AO1: Съдържание на мед в медния к-т /химия-товарен/ | AP1: Метал мед в медния концентрат | AQ1: Метал мед в медния концентрат /химия/ | AR1: Литрово тегло в сгъстителя | AS1: Меден концентрат, автомобилна везна | AT1: Меден концентрат в склад | AU1: Меден концентрат в склад | AV1: Добит молибденов концентрат | AW1: Съдържание на Мо в молибденовия к-т | AX1: последни данни за съдържания в 8-ма пречистка | AZ1: последни данни за съдържания във 2-ра пречистка
D2: тона | E2: метра | F2: тона | G2: % | H2: % | I2: тона | J2: метра | K2: тона | L2: % | M2: тона | N2: % | P2: % | R2: % | S2: % | U2: % | W2: % | Y2: % | AA2: % | AB2: % | AC2: % | AD2: % | AE2: тона | AF2: % | AG2: тона | AH2: % | AI2: % | AJ2: тона | AK2: % | AL2: % | AM2: % | AN2: тона | AO2: тона | AP2: кг/литър | AQ2: тон | AR2: тон | AS2: тон | AT2: кг. | AU2: % | AV2: Мо % | AW2: Cu % | AX2: Мо % | AY2: Cu %
AR3: 1488.04
A4: 1 | B4: 1 | C4: Димитър Цончев | D4: 15768 | E4: 1 | F4: 15694 | G4: 2.4 | H4: 4.8 | I4: 17126 | J4: 6.1 | K4: 15129 | L4: 0.079 | M4: =ROUND(K4*(1-L4),0) -> 13934 | N4: 0.559 | O4: =M4*N4 -> 7789.106 | P4: 0.399 | Q4: =M4*P4 -> 5559.666 | R4: 0.042 | S4: 0.2019 | T4: =M4*R4 -> 585.228 | U4: 0.186 | V4: =M4*U4 -> 2591.724 | W4: 0.521 | X4: =M4*W4 -> 7259.614 | Y4: 0.37 | Z4: =Y4*M4 -> 5155.58 | AA4: 0.00248 | AB4: =M4*AA4 -> 34.55632 | AC4: =IF(M4>0,(AE4+AN4)/M4,0) -> 0.0027201061 | AD4: 0.0003 | AE4: =AD4*M4 -> 4.1802 | AF4: 0.2115 | AG4: =AJ4*(1-AK4)*AF4 -> 34.91019 | AH4: =IF(AND(AF4>0,AD4>0,AA4>0),((AA4-AD4)*AF4)/((AF4-AD4)*AA4),0) -> 0.88028088 | AI4: =IF(AND(AC4>0,AL4>0,AD4>0),((AL4*(AC4-AD4))/(AC4*(AL4-AD4))),0) -> 0.89101858 | AJ4: 180 | AK4: 0.083 | AL4: 0.2043 | AM4: 0.2055 | AN4: =AJ4*(1-AK4)*AL4 -> 33.721758 | AO4: =AJ4*(1-AK4)*AM4 -> 33.91983 | AP4: 1.55 | AR4: =AR3+AJ4-AQ4 -> 1668.04
B5: 2 | C5: Георги Томов | D5: 18500 | E5: 2 | F5: 14303 | G5: 2.6 | H5: 4 | I5: 15594 | J5: 6.2 | K5: 15357 | L5: 0.085 | M5: =ROUND(K5*(1-L5),0) -> 14052 | N5: 0.709 | O5: =M5*N5 -> 9962.868 | P5: 0.243 | Q5: =M5*P5 -> 3414.636 | R5: 0.048 | T5: =M5*R5 -> 674.496 | U5: 0.175 | V5: =M5*U5 -> 2459.1 | W5: 0.538 | X5: =M5*W5 -> 7559.976 | Y5: 0.36 | Z5: =Y5*M5 -> 5058.72 | AA5: 0.00262 | AB5: =M5*AA5 -> 36.81624 | AC5: =IF(M5>0,(AE5+AN5)/M5,0) -> 0.0027337537 | AD5: 0.00031 | AE5: =AD5*M5 -> 4.35612 | AF5: 0.2166 | AG5: =AJ5*(1-AK5)*AF5 -> 34.683075 | AH5: =IF(AND(AF5>0,AD5>0,AA5>0),((AA5-AD5)*AF5)/((AF5-AD5)*AA5),0) -> 0.88294307 | AI5: =IF(AND(AC5>0,AL5>0,AD5>0),((AL5*(AC5-AD5))/(AC5*(AL5-AD5))),0) -> 0.88789687 | AJ5: 175 | AK5: 0.085 | AL5: 0.2127 | AM5: 0.2183 | AN5: =AJ5*(1-AK5)*AL5 -> 34.058588 | AO5: =AJ5*(1-AK5)*AM5 -> 34.955287 | AP5: 1.55 | AR5: =AR4+AJ5-AQ5 -> 1843.04
B6: 3 | C6: Николинка Мутафова | D6: 17022 | E6: 0 | F6: 15083 | G6: 2.3 | H6: 5.3 | I6: 16438 | J6: 5.8 | K6: 15521 | L6: 0.095 | M6: =ROUND(K6*(1-L6),0) -> 14047 | N6: 0.733 | O6: =M6*N6 -> 10296.451 | P6: 0.189 | Q6: =M6*P6 -> 2654.883 | R6: 0.078 | T6: =M6*R6 -> 1095.666 | U6: 0.182 | V6: =M6*U6 -> 2556.554 | W6: 0.537 | X6: =M6*W6 -> 7543.239 | Y6: 0.38 | Z6: =Y6*M6 -> 5337.86 | AA6: 0.00243 | AB6: =M6*AA6 -> 34.13421 | AC6: =IF(M6>0,(AE6+AN6)/M6,0) -> 0.0026101976 | AD6: 0.0003 | AE6: =AD6*M6 -> 4.2141 | AF6: 0.2157 | AG6: =AJ6*(1-AK6)*AF6 -> 33.427676 | AH6: =IF(AND(AF6>0,AD6>0,AA6>0),((AA6-AD6)*AF6)/((AF6-AD6)*AA6),0) -> 0.87776402 | AI6: =IF(AND(AC6>0,AL6>0,AD6>0),((AL6*(AC6-AD6))/(AC6*(AL6-AD6))),0) -> 0.886336 | AJ6: 169 | AK6: 0.083 | AL6: 0.2094 | AM6: 0.2131 | AN6: =AJ6*(1-AK6)*AL6 -> 32.451346 | AO6: =AJ6*(1-AK6)*AM6 -> 33.024746 | AP6: 1.55 | AR6: =AR5+AJ6-AQ6 -> 2012.04
B7: Общо | D7: =SUM(D4:D6) -> 51290 | F7: =SUM(F4:F6) -> 45080 | I7: =SUM(I4:I6) -> 49158 | K7: =SUM(K4:K6) -> 46007 | L7: =IF(K7>0,(K4*L4+K5*L5+K6*L6)/K7,0) -> 0.086400569 | M7: =M4+M5+M6 -> 42033 | N7: =IF(M7>0,O7/M7,0) -> 0.66729534 | O7: =O4+O5+O6 -> 28048.425 | P7: =IF(M7>0,Q7/M7,0) -> 0.27666798 | Q7: =Q4+Q5+Q6 -> 11629.185 | R7: =IF(M7>0,T7/M7,0) -> 0.056036685 | T7: =T4+T5+T6 -> 2355.39 | U7: =IF(M7>0,V7/M7,0) -> 0.18098584 | V7: =V4+V5+V6 -> 7607.378 | W7: =IF(M7>0,X7/M7,0) -> 0.53203029 | X7: =X4+X5+X6 -> 22362.829 | Y7: =IF(M7>0,Z7/M7,0) -> 0.36999881 | Z7: =Z4+Z5+Z6 -> 15552.16 | AA7: =IF(M7>0,AB7/M7,0) -> 0.0025100937 | AB7: =SUM(AB4:AB6) -> 105.50677 | AC7: =IF(M7>0,(AC4*M4+AC5*M5+AC6*M6)/M7,0) -> 0.0026879383 | AD7: =IF(K7>0,(K4*AD4+K5*AD5+K6*AD6)/K7,0) -> 0.00030333797 | AE7: =SUM(AE4:AE6) -> 12.75042 | AF7: =IF(K7>0,(K4*AF4+K5*AF5+K6*AF6)/K7,0) -> 0.21461928 | AG7: =SUM(AG4:AG6) -> 103.02094 | AH7: =IF(AND(AB7>0),((AB4*AH4+AB5*AH5+AB6*AH6)/AB7),0) -> 0.88039557 | AI7: =IF(AND(AC7>0,AL7>0,AD7>0),((AL7*(AC7-AD7))/(AC7*(AL7-AD7))),0) -> 0.88843901 | AJ7: =SUM(AJ4:AJ6) -> 524 | AK7: =IF(AJ7>0,(AK4*AJ4+AK5*AJ5+AK6*AJ6)/AJ7,0) -> 0.083667939 | AL7: =IF(K7>0,(AL4*K4+AL5*K5+AL6*K6)/K7,0) -> 0.20882444 | AM7: =IF(K7>0,(AM4*K4+AM5*K5+AM6*K6)/K7,0) -> 0.21233655 | AN7: =SUM(AN4:AN6) -> 100.23169 | AO7: =SUM(AO4:AO6) -> 101.89986 | AQ7: =SUM(AQ4:AQ6) -> 0 | AS7: =AR6 -> 2012.04 | AT7: =SUM(AT4:AT6) -> 0
A8: 2 | B8: 1 | C8: Димитър Цончев | D8: 5711 | E8: 0 | F8: 11636 | G8: 1.6 | H8: 6.6 | I8: 12562 | J8: 7 | K8: 16160 | L8: 0.087 | M8: =ROUND(K8*(1-L8),0) -> 14754 | N8: 0.627 | O8: =M8*N8 -> 9250.758 | P8: 0.323 | Q8: =M8*P8 -> 4765.542 | R8: 0.05 | S8: 0.226 | T8: =M8*R8 -> 737.7 | U8: 0.193 | V8: =M8*U8 -> 2847.522 | W8: 0.532 | X8: =M8*W8 -> 7849.128 | Y8: 0.38 | Z8: =Y8*M8 -> 5606.52 | AA8: 0.00237 | AB8: =M8*AA8 -> 34.96698 | AC8: =IF(M8>0,(AE8+AN8)/M8,0) -> 0.0025798108 | AD8: 0.00029 | AE8: =AD8*M8 -> 4.27866 | AF8: 0.2164 | AG8: =AJ8*(1-AK8)*AF8 -> 34.963315 | AH8: =IF(AND(AF8>0,AD8>0,AA8>0),((AA8-AD8)*AF8)/((AF8-AD8)*AA8),0) -> 0.87881484 | AI8: =IF(AND(AC8>0,AL8>0,AD8>0),((AL8*(AC8-AD8))/(AC8*(AL8-AD8))),0) -> 0.88882136 | AJ8: 176 | AK8: 0.082 | AL8: 0.2091 | AM8: 0.2176 | AN8: =AJ8*(1-AK8)*AL8 -> 33.783869 | AO8: =AJ8*(1-AK8)*AM8 -> 35.157197 | AP8: 1.6 | AQ8: 1120.04 | AR8: =AR6+AJ8-AQ8 -> 1068
B9: 2 | C9: Иванка Копаранска | D9: 18500 | E9: 3 | F9: 14132 | G9: 1.5 | H9: 5.1 | I9: 15743 | J9: 6.7 | K9: 16138 | L9: 0.082 | M9: =ROUND(K9*(1-L9),0) -> 14815 | N9: 0.591 | O9: =M9*N9 -> 8755.665 | P9: 0.349 | Q9: =M9*P9 -> 5170.435 | R9: 0.06 | S9: 0.227 | T9: =M9*R9 -> 888.9 | U9: 0.213 | V9: =M9*U9 -> 3155.595 | W9: 0.506 | X9: =M9*W9 -> 7496.39 | Y9: 0.37 | Z9: =Y9*M9 -> 5481.55 | AA9: 0.0024 | AB9: =M9*AA9 -> 35.556 | AC9: =IF(M9>0,(AE9+AN9)/M9,0) -> 0.0024893922 | AD9: 0.00028 | AE9: =AD9*M9 -> 4.1482 | AF9: 0.215 | AG9: =AJ9*(1-AK9)*AF9 -> 32.97756 | AH9: =IF(AND(AF9>0,AD9>0,AA9>0),((AA9-AD9)*AF9)/((AF9-AD9)*AA9),0) -> 0.88448522 | AI9: =IF(AND(AC9>0,AL9>0,AD9>0),((AL9*(AC9-AD9))/(AC9*(AL9-AD9))),0) -> 0.88868879 | AJ9: 168 | AK9: 0.087 | AL9: 0.2134 | AM9: 0.2206 | AN9: =AJ9*(1-AK9)*AL9 -> 32.732146 | AO9: =AJ9*(1-AK9)*AM9 -> 33.83651 | AP9: 1.6 | AR9: =AR8+AJ9-AQ9 -> 1236
B10: 3 | C10: Николинка Мутафова | D10: 20214 | E10: 0 | F10: 16348 | G10: 2.8 | H10: 5.9 | I10: 17496 | J10: 6.4 | K10: 16211 | L10: 0.083 | M10: =ROUND(K10*(1-L10),0) -> 14865 | N10: 0.696 | O10: =M10*N10 -> 10346.04 | P10: 0.228 | Q10: =M10*P10 -> 3389.22 | R10: 0.076 | S10: 0.2177 | T10: =M10*R10 -> 1129.74 | U10: 0.238 | V10: =M10*U10 -> 3537.87 | W10: 0.476 | X10: =M10*W10 -> 7075.74 | Y10: 0.39 | Z10: =Y10*M10 -> 5797.35 | AA10: 0.00229 | AB10: =M10*AA10 -> 34.04085 | AC10: =IF(M10>0,(AE10+AN10)/M10,0) -> 0.0024921887 | AD10: 0.00028 | AE10: =AD10*M10 -> 4.1622 | AF10: 0.2174 | AG10: =AJ10*(1-AK10)*AF10 -> 33.020886 | AH10: =IF(AND(AF10>0,AD10>0,AA10>0),((AA10-AD10)*AF10)/((AF10-AD10)*AA10),0) -> 0.87886119 | AI10: =IF(AND(AC10>0,AL10>0,AD10>0),((AL10*(AC10-AD10))/(AC10*(AL10-AD10))),0) -> 0.88879844 | AJ10: 166 | AK10: 0.085 | AL10: 0.2165 | AM10: 0.2243 | AN10: =AJ10*(1-AK10)*AL10 -> 32.884185 | AO10: =AJ10*(1-AK10)*AM10 -> 34.068927 | AP10: 1.6 | AR10: =AR9+AJ10-AQ10 -> 1402
B11: Общо | D11: =SUM(D8:D10) -> 44425 | F11: =SUM(F8:F10) -> 42116 | I11: =SUM(I8:I10) -> 45801 | K11: =SUM(K8:K10) -> 48509 | L11: =IF(K11>0,(K8*L8+K9*L9+K10*L10)/K11,0) -> 0.083999856 | M11: =M8+M9+M10 -> 44434 | N11: =IF(M11>0,O11/M11,0) -> 0.63808037 | O11: =O8+O9+O10 -> 28352.463 | P11: =IF(M11>0,Q11/M11,0) -> 0.29988741 | Q11: =Q8+Q9+Q10 -> 13325.197 | R11: =IF(M11>0,T11/M11,0) -> 0.062032228 | T11: =T8+T9+T10 -> 2756.34 | U11: =IF(M11>0,V11/M11,0) -> 0.21472267 | V11: =V8+V9+V10 -> 9540.987 | W11: =IF(M11>0,X11/M11,0) -> 0.50459689 | X11: =X8+X9+X10 -> 22421.258 | Y11: =IF(M11>0,Z11/M11,0) -> 0.38001125 | Z11: =Z8+Z9+Z10 -> 16885.42 | AA11: =IF(M11>0,AB11/M11,0) -> 0.0023532392 | AB11: =SUM(AB8:AB10) -> 104.56383 | AC11: =IF(M11>0,(AC8*M8+AC9*M9+AC10*M10)/M11,0) -> 0.0025203506 | AD11: =IF(K11>0,(K8*AD8+K9*AD9+K10*AD10)/K11,0) -> 0.00028333134 | AE11: =SUM(AE8:AE10) -> 12.58906 | AF11: =IF(K11>0,(K8*AF8+K9*AF9+K10*AF10)/K11,0) -> 0.21626843 | AG11: =SUM(AG8:AG10) -> 100.96176 | AH11: =IF(AND(AB11>0),((AB8*AH8+AB9*AH9+AB10*AH10)/AB11),0) -> 0.88075809 | AI11: =IF(AND(AC11>0,AL11>0,AD11>0),((AL11*(AC11-AD11))/(AC11*(AL11-AD11))),0) -> 0.88876478 | AJ11: =SUM(AJ8:AJ10) -> 510 | AK11: =IF(AJ11>0,(AK8*AJ8+AK9*AJ9+AK10*AJ10)/AJ11,0) -> 0.084623529 | AL11: =IF(K11>0,(AL8*K8+AL9*K9+AL10*K10)/K11,0) -> 0.2130035 | AM11: =IF(K11>0,(AM8*K8+AM9*K9+AM10*K10)/K11,0) -> 0.22083708 | AN11: =SUM(AN8:AN10) -> 99.400199 | AO11: =SUM(AO8:AO10) -> 103.06263 | AQ11: =SUM(AQ8:AQ10) -> 1120.04 | AS11: =AR10 -> 1402 | AT11: =SUM(AT8:AT10) -> 0
A12: 3 | B12: 1 | C12: Димитър Цончев | D12: 3899 | E12: 0 | F12: 8147 | G12: 2.3 | H12: 5 | I12: 9962 | J12: 8.5 | K12: 16143 | L12: 0.076 | M12: =ROUND(K12*(1-L12),0) -> 14916 | N12: 0.596 | O12: =M12*N12 -> 8889.936 | P12: 0.378 | Q12: =M12*P12 -> 5638.248 | R12: 0.026 | S12: 0.1873 | T12: =M12*R12 -> 387.816 | U12: 0.21 | V12: =M12*U12 -> 3132.36 | W12: 0.501 | X12: =M12*W12 -> 7472.916 | Y12: 0.39 | Z12: =Y12*M12 -> 5817.24 | AA12: 0.00244 | AB12: =M12*AA12 -> 36.39504 | AC12: =IF(M12>0,(AE12+AN12)/M12,0) -> 0.0026126926 | AD12: 0.00028 | AE12: =AD12*M12 -> 4.17648 | AF12: 0.2117 | AG12: =AJ12*(1-AK12)*AF12 -> 34.517262 | AH12: =IF(AND(AF12>0,AD12>0,AA12>0),((AA12-AD12)*AF12)/((AF12-AD12)*AA12),0) -> 0.8864183 | AI12: =IF(AND(AC12>0,AL12>0,AD12>0),((AL12*(AC12-AD12))/(AC12*(AL12-AD12))),0) -> 0.89400388 | AJ12: 178 | AK12: 0.084 | AL12: 0.2134 | AM12: 0.2148 | AN12: =AJ12*(1-AK12)*AL12 -> 34.794443 | AO12: =AJ12*(1-AK12)*AM12 -> 35.02271 | AP12: 1.58 | AQ12: 1000.34 | AR12: =AR10+AJ12-AQ12 -> 579.66
B13: 2 | C13: Иванка Копаранска | D13: 20366 | E13: 2 | F13: 14795 | G13: 2 | H13: 5 | I13: 16667 | J13: 7.8 | K13: 16116 | L13: 0.079 | M13: =ROUND(K13*(1-L13),0) -> 14843 | N13: 0.614 | O13: =M13*N13 -> 9113.602 | P13: 0.359 | Q13: =M13*P13 -> 5328.637 | R13: 0.027 | S13: 0.2043 | T13: =M13*R13 -> 400.761 | U13: 0.203 | V13: =M13*U13 -> 3013.129 | W13: 0.507 | X13: =M13*W13 -> 7525.401 | Y13: 0.39 | Z13: =Y13*M13 -> 5788.77 | AA13: 0.00247 | AB13: =M13*AA13 -> 36.66221 | AC13: =IF(M13>0,(AE13+AN13)/M13,0) -> 0.0027489337 | AD13: 0.00027 | AE13: =AD13*M13 -> 4.00761 | AF13: 0.2108 | AG13: =AJ13*(1-AK13)*AF13 -> 36.759936 | AH13: =IF(AND(AF13>0,AD13>0,AA13>0),((AA13-AD13)*AF13)/((AF13-AD13)*AA13),0) -> 0.89183055 | AI13: =IF(AND(AC13>0,AL13>0,AD13>0),((AL13*(AC13-AD13))/(AC13*(AL13-AD13))),0) -> 0.90293551 | AJ13: 191 | AK13: 0.087 | AL13: 0.211 | AM13: 0.2108 | AN13: =AJ13*(1-AK13)*AL13 -> 36.794813 | AO13: =AJ13*(1-AK13)*AM13 -> 36.759936 | AP13: 1.6 | AR13: =AR12+AJ13-AQ13 -> 770.66
B14: 3 | C14: Цвета Владова | D14: 17375 | E14: 1 | F14: 16111 | G14: 1.7 | H14: 5 | I14: 17673 | J14: 7.5 | K14: 16130 | L14: 0.086 | M14: =ROUND(K14*(1-L14),0) -> 14743 | N14: 0.54 | O14: =M14*N14 -> 7961.22 | P14: 0.397 | Q14: =M14*P14 -> 5852.971 | R14: 0.063 | S14: 0.205 | T14: =M14*R14 -> 928.809 | U14: 0.224 | V14: =M14*U14 -> 3302.432 | W14: 0.489 | X14: =M14*W14 -> 7209.327 | Y14: 0.39 | Z14: =Y14*M14 -> 5749.77 | AA14: 0.00236 | AB14: =M14*AA14 -> 34.79348 | AC14: =IF(M14>0,(AE14+AN14)/M14,0) -> 0.0026690904 | AD14: 0.00027 | AE14: =AD14*M14 -> 3.98061 | AF14: 0.2156 | AG14: =AJ14*(1-AK14)*AF14 -> 35.66757 | AH14: =IF(AND(AF14>0,AD14>0,AA14>0),((AA14-AD14)*AF14)/((AF14-AD14)*AA14),0) -> 0.88670366 | AI14: =IF(AND(AC14>0,AL14>0,AD14>0),((AL14*(AC14-AD14))/(AC14*(AL14-AD14))),0) -> 0.89997849 | AJ14: 181 | AK14: 0.086 | AL14: 0.2138 | AM14: 0.2153 | AN14: =AJ14*(1-AK14)*AL14 -> 35.369789 | AO14: =AJ14*(1-AK14)*AM14 -> 35.61794 | AP14: 1.6 | AR14: =AR13+AJ14-AQ14 -> 951.66
B15: Общо | D15: =SUM(D12:D14) -> 41640 | F15: =SUM(F12:F14) -> 39053 | I15: =SUM(I12:I14) -> 44302 | K15: =SUM(K12:K14) -> 48389 | L15: =IF(K15>0,(K12*L12+K13*L13+K14*L14)/K15,0) -> 0.080332555 | M15: =M12+M13+M14 -> 44502 | N15: =IF(M15>0,O15/M15,0) -> 0.58345149 | O15: =O12+O13+O14 -> 25964.758 | P15: =IF(M15>0,Q15/M15,0) -> 0.37795731 | Q15: =Q12+Q13+Q14 -> 16819.856 | R15: =IF(M15>0,T15/M15,0) -> 0.038591209 | T15: =T12+T13+T14 -> 1717.386 | U15: =IF(M15>0,V15/M15,0) -> 0.21230329 | V15: =V12+V13+V14 -> 9447.921 | W15: =IF(M15>0,X15/M15,0) -> 0.49902575 | X15: =X12+X13+X14 -> 22207.644 | Y15: =IF(M15>0,Z15/M15,0) -> 0.39 | Z15: =Z12+Z13+Z14 -> 17355.78 | AA15: =IF(M15>0,AB15/M15,0) -> 0.002423503 | AB15: =SUM(AB12:AB14) -> 107.85073 | AC15: =IF(M15>0,(AC12*M12+AC13*M13+AC14*M14)/M15,0) -> 0.0026768178 | AD15: =IF(K15>0,(K12*AD12+K13*AD13+K14*AD14)/K15,0) -> 0.00027333609 | AE15: =SUM(AE12:AE14) -> 12.1647 | AF15: =IF(K15>0,(K12*AF12+K13*AF13+K14*AF14)/K15,0) -> 0.21270028 | AG15: =SUM(AG12:AG14) -> 106.94477 | AH15: =IF(AND(AB15>0),((AB12*AH12+AB13*AH13+AB14*AH14)/AB15),0) -> 0.88835017 | AI15: =IF(AND(AC15>0,AL15>0,AD15>0),((AL15*(AC15-AD15))/(AC15*(AL15-AD15))),0) -> 0.89904283 | AJ15: =SUM(AJ12:AJ14) -> 550 | AK15: =IF(AJ15>0,(AK12*AJ12+AK13*AJ13+AK14*AJ14)/AJ15,0) -> 0.0857 | AL15: =IF(K15>0,(AL12*K12+AL13*K13+AL14*K14)/K15,0) -> 0.21273401 | AM15: =IF(K15>0,(AM12*K12+AM13*K13+AM14*K14)/K15,0) -> 0.21363447 | AN15: =SUM(AN12:AN14) -> 106.95905 | AO15: =SUM(AO12:AO14) -> 107.40059 | AQ15: =SUM(AQ12:AQ14) -> 1000.34 | AS15: =AR14 -> 951.66 | AT15: =SUM(AT12:AT14) -> 0
A16: 4 | B16: 1 | C16: Георги Томов | D16: 12100 | E16: 0 | F16: 15839 | G16: 1.6 | H16: 3.9 | I16: 17263 | J16: 7 | K16: 16115 | L16: 0.082 | M16: =ROUND(K16*(1-L16),0) -> 14794 | N16: 0.581 | O16: =M16*N16 -> 8595.314 | P16: 0.366 | Q16: =M16*P16 -> 5414.604 | R16: 0.053 | S16: 0.207 | T16: =M16*R16 -> 784.082 | U16: 0.203 | V16: =M16*U16 -> 3003.182 | W16: 0.5 | X16: =M16*W16 -> 7397 | Y16: 0.39 | Z16: =Y16*M16 -> 5769.66 | AA16: 0.00245 | AB16: =M16*AA16 -> 36.2453 | AC16: =IF(M16>0,(AE16+AN16)/M16,0) -> 0.0025011805 | AD16: 0.00028 | AE16: =AD16*M16 -> 4.14232 | AF16: 0.2142 | AG16: =AJ16*(1-AK16)*AF16 -> 32.998795 | AH16: =IF(AND(AF16>0,AD16>0,AA16>0),((AA16-AD16)*AF16)/((AF16-AD16)*AA16),0) -> 0.8868736 | AI16: =IF(AND(AC16>0,AL16>0,AD16>0),((AL16*(AC16-AD16))/(AC16*(AL16-AD16))),0) -> 0.88922015 | AJ16: 168 | AK16: 0.083 | AL16: 0.2133 | AM16: 0.2133 | AN16: =AJ16*(1-AK16)*AL16 -> 32.860145 | AO16: =AJ16*(1-AK16)*AM16 -> 32.860145 | AP16: 1.55 | AR16: =AR14+AJ16-AQ16 -> 1119.66
B17: 2 | C17: Иванка Копаранска | D17: 19265 | E17: 2 | F17: 15284 | G17: 0.9 | H17: 4.4 | I17: 17470 | J17: 6.7 | K17: 16166 | L17: 0.085 | M17: =ROUND(K17*(1-L17),0) -> 14792 | N17: 0.638 | O17: =M17*N17 -> 9437.296 | P17: 0.301 | Q17: =M17*P17 -> 4452.392 | R17: 0.061 | S17: 0.2057 | T17: =M17*R17 -> 902.312 | U17: 0.199 | V17: =M17*U17 -> 2943.608 | W17: 0.516 | X17: =M17*W17 -> 7632.672 | Y17: 0.38 | Z17: =Y17*M17 -> 5620.96 | AA17: 0.00245 | AB17: =M17*AA17 -> 36.2404 | AC17: =IF(M17>0,(AE17+AN17)/M17,0) -> 0.0026826051 | AD17: 0.00028 | AE17: =AD17*M17 -> 4.14176 | AF17: 0.222 | AG17: =AJ17*(1-AK17)*AF17 -> 35.993304 | AH17: =IF(AND(AF17>0,AD17>0,AA17>0),((AA17-AD17)*AF17)/((AF17-AD17)*AA17),0) -> 0.88683281 | AI17: =IF(AND(AC17>0,AL17>0,AD17>0),((AL17*(AC17-AD17))/(AC17*(AL17-AD17))),0) -> 0.89676935 | AJ17: 177 | AK17: 0.084 | AL17: 0.2192 | AM17: 0.2249 | AN17: =AJ17*(1-AK17)*AL17 -> 35.539334 | AO17: =AJ17*(1-AK17)*AM17 -> 36.463487 | AP17: 1.6 | AR17: =AR16+AJ17-AQ17 -> 1296.66
B18: 3 | C18: Цвета Владова | D18: 17875 | E18: 1 | F18: 15652 | G18: 1.2 | H18: 5.3 | I18: 17476 | J18: 6.2 | K18: 16148 | L18: 0.082 | M18: =ROUND(K18*(1-L18),0) -> 14824 | N18: 0.724 | O18: =M18*N18 -> 10732.576 | P18: 0.255 | Q18: =M18*P18 -> 3780.12 | R18: 0.021 | S18: 0.2066 | T18: =M18*R18 -> 311.304 | U18: 0.205 | V18: =M18*U18 -> 3038.92 | W18: 0.5 | X18: =M18*W18 -> 7412 | Y18: 0.39 | Z18: =Y18*M18 -> 5781.36 | AA18: 0.0025 | AB18: =M18*AA18 -> 37.06 | AC18: =IF(M18>0,(AE18+AN18)/M18,0) -> 0.0028660577 | AD18: 0.00028 | AE18: =AD18*M18 -> 4.15072 | AF18: 0.2176 | AG18: =AJ18*(1-AK18)*AF18 -> 38.583962 | AH18: =IF(AND(AF18>0,AD18>0,AA18>0),((AA18-AD18)*AF18)/((AF18-AD18)*AA18),0) -> 0.88914412 | AI18: =IF(AND(AC18>0,AL18>0,AD18>0),((AL18*(AC18-AD18))/(AC18*(AL18-AD18))),0) -> 0.90347492 | AJ18: 194 | AK18: 0.086 | AL18: 0.2162 | AM18: 0.2118 | AN18: =AJ18*(1-AK18)*AL18 -> 38.335719 | AO18: =AJ18*(1-AK18)*AM18 -> 37.555529 | AP18: 1.6 | AR18: =AR17+AJ18-AQ18 -> 1490.66
B19: Общо | D19: =SUM(D16:D18) -> 49240 | F19: =SUM(F16:F18) -> 46775 | I19: =SUM(I16:I18) -> 52209 | K19: =SUM(K16:K18) -> 48429 | L19: =IF(K19>0,(K16*L16+K17*L17+K18*L18)/K19,0) -> 0.083001425 | M19: =M16+M17+M18 -> 44410 | N19: =IF(M19>0,O19/M19,0) -> 0.64771867 | O19: =O16+O17+O18 -> 28765.186 | P19: =IF(M19>0,Q19/M19,0) -> 0.30729827 | Q19: =Q16+Q17+Q18 -> 13647.116 | R19: =IF(M19>0,T19/M19,0) -> 0.044983067 | T19: =T16+T17+T18 -> 1997.698 | U19: =IF(M19>0,V19/M19,0) -> 0.20233528 | V19: =V16+V17+V18 -> 8985.71 | W19: =IF(M19>0,X19/M19,0) -> 0.50532925 | X19: =X16+X17+X18 -> 22441.672 | Y19: =IF(M19>0,Z19/M19,0) -> 0.38666922 | Z19: =Z16+Z17+Z18 -> 17171.98 | AA19: =IF(M19>0,AB19/M19,0) -> 0.0024666899 | AB19: =SUM(AB16:AB18) -> 109.5457 | AC19: =IF(M19>0,(AC16*M16+AC17*M17+AC18*M18)/M19,0) -> 0.0026834046 | AD19: =IF(K19>0,(K16*AD16+K17*AD17+K18*AD18)/K19,0) -> 0.00028 | AE19: =SUM(AE16:AE18) -> 12.4348 | AF19: =IF(K19>0,(K16*AF16+K17*AF17+K18*AF18)/K19,0) -> 0.21793739 | AG19: =SUM(AG16:AG18) -> 107.57606 | AH19: =IF(AND(AB19>0),((AB16*AH16+AB17*AH17+AB18*AH18)/AB19),0) -> 0.88762824 | AI19: =IF(AND(AC19>0,AL19>0,AD19>0),((AL19*(AC19-AD19))/(AC19*(AL19-AD19))),0) -> 0.89681621 | AJ19: =SUM(AJ16:AJ18) -> 539 | AK19: =IF(AJ19>0,(AK16*AJ16+AK17*AJ17+AK18*AJ18)/AJ19,0) -> 0.084408163 | AL19: =IF(K19>0,(AL16*K16+AL17*K17+AL18*K18)/K19,0) -> 0.21623643 | AM19: =IF(K19>0,(AM16*K16+AM17*K17+AM18*K18)/K19,0) -> 0.21667202 | AN19: =SUM(AN16:AN18) -> 106.7352 | AO19: =SUM(AO16:AO18) -> 106.87916 | AQ19: =SUM(AQ16:AQ18) -> 0 | AS19: =AR18 -> 1490.66 | AT19: =SUM(AT16:AT18) -> 0
A20: 5 | B20: 1 | C20: Георги Томов | D20: 12600 | E20: 0 | F20: 15540 | G20: 1.2 | H20: 4.6 | I20: 17368 | J20: 6 | K20: 16152 | L20: 0.079 | M20: =ROUND(K20*(1-L20),0) -> 14876 | N20: 0.723 | O20: =M20*N20 -> 10755.348 | P20: 0.254 | Q20: =M20*P20 -> 3778.504 | R20: 0.022 | S20: 0.2044 | T20: =M20*R20 -> 327.272 | U20: 0.202 | V20: =M20*U20 -> 3004.952 | W20: 0.516 | X20: =M20*W20 -> 7676.016 | Y20: 0.39 | Z20: =Y20*M20 -> 5801.64 | AA20: 0.00248 | AB20: =M20*AA20 -> 36.89248 | AC20: =IF(M20>0,(AE20+AN20)/M20,0) -> 0.0025649009 | AD20: 0.00029 | AE20: =AD20*M20 -> 4.31404 | AF20: 0.2177 | AG20: =AJ20*(1-AK20)*AF20 -> 35.334669 | AH20: =IF(AND(AF20>0,AD20>0,AA20>0),((AA20-AD20)*AF20)/((AF20-AD20)*AA20),0) -> 0.88424242 | AI20: =IF(AND(AC20>0,AL20>0,AD20>0),((AL20*(AC20-AD20))/(AC20*(AL20-AD20))),0) -> 0.88817055 | AJ20: 177 | AK20: 0.083 | AL20: 0.2085 | AM20: 0.2169 | AN20: =AJ20*(1-AK20)*AL20 -> 33.841426 | AO20: =AJ20*(1-AK20)*AM20 -> 35.204822 | AP20: 1.65 | AR20: =AR18+AJ20-AQ20-AS20+AS20+AS20 -> 1667.66
B21: 2 | C21: Николинка Мутафова | D21: 18255 | E21: 2 | F21: 15522 | G21: 1.6 | H21: 5.4 | I21: 17479 | J21: 5.5 | K21: 16149 | L21: 0.086 | M21: =ROUND(K21*(1-L21),0) -> 14760 | N21: 0.686 | O21: =M21*N21 -> 10125.36 | P21: 0.235 | Q21: =M21*P21 -> 3468.6 | R21: 0.079 | S21: 0.2049 | T21: =M21*R21 -> 1166.04 | U21: 0.2 | V21: =M21*U21 -> 2952 | W21: 0.514 | X21: =M21*W21 -> 7586.64 | Y21: 0.38 | Z21: =Y21*M21 -> 5608.8 | AA21: 0.00258 | AB21: =M21*AA21 -> 38.0808 | AC21: =IF(M21>0,(AE21+AN21)/M21,0) -> 0.0027512119 | AD21: 0.00029 | AE21: =AD21*M21 -> 4.2804 | AF21: 0.2123 | AG21: =AJ21*(1-AK21)*AF21 -> 35.938144 | AH21: =IF(AND(AF21>0,AD21>0,AA21>0),((AA21-AD21)*AF21)/((AF21-AD21)*AA21),0) -> 0.88881101 | AI21: =IF(AND(AC21>0,AL21>0,AD21>0),((AL21*(AC21-AD21))/(AC21*(AL21-AD21))),0) -> 0.89580245 | AJ21: 184 | AK21: 0.08 | AL21: 0.2146 | AM21: 0.2141 | AN21: =AJ21*(1-AK21)*AL21 -> 36.327488 | AO21: =AJ21*(1-AK21)*AM21 -> 36.242848 | AP21: 1.65 | AR21: =AR20+AJ21-AQ21 -> 1851.66
B22: 3 | C22: Цвета Владова | D22: 17795 | E22: 1 | F22: 15273 | G22: 1.3 | H22: 3.3 | I22: 16953 | J22: 5.6 | K22: 16101 | L22: 0.078 | M22: =ROUND(K22*(1-L22),0) -> 14845 | N22: 0.528 | O22: =M22*N22 -> 7838.16 | P22: 0.334 | Q22: =M22*P22 -> 4958.23 | R22: 0.138 | S22: 0.2112 | T22: =M22*R22 -> 2048.61 | U22: 0.206 | V22: =M22*U22 -> 3058.07 | W22: 0.505 | X22: =M22*W22 -> 7496.725 | Y22: 0.39 | Z22: =Y22*M22 -> 5789.55 | AA22: 0.00245 | AB22: =M22*AA22 -> 36.37025 | AC22: =IF(M22>0,(AE22+AN22)/M22,0) -> 0.0028349729 | AD22: 0.00029 | AE22: =AD22*M22 -> 4.30505 | AF22: 0.2176 | AG22: =AJ22*(1-AK22)*AF22 -> 38.541747 | AH22: =IF(AND(AF22>0,AD22>0,AA22>0),((AA22-AD22)*AF22)/((AF22-AD22)*AA22),0) -> 0.88280919 | AI22: =IF(AND(AC22>0,AL22>0,AD22>0),((AL22*(AC22-AD22))/(AC22*(AL22-AD22))),0) -> 0.89892842 | AJ22: 194 | AK22: 0.087 | AL22: 0.2133 | AM22: 0.2174 | AN22: =AJ22*(1-AK22)*AL22 -> 37.780123 | AO22: =AJ22*(1-AK22)*AM22 -> 38.506323 | AP22: 1.6 | AR22: =AR21+AJ22-AQ22 -> 2045.66
B23: Общо | D23: =SUM(D20:D22) -> 48650 | F23: =SUM(F20:F22) -> 46335 | I23: =SUM(I20:I22) -> 51800 | K23: =SUM(K20:K22) -> 48402 | L23: =IF(K23>0,(K20*L20+K21*L21+K22*L22)/K23,0) -> 0.081002851 | M23: =M20+M21+M22 -> 44481 | N23: =IF(M23>0,O23/M23,0) -> 0.64564349 | O23: =O20+O21+O22 -> 28718.868 | P23: =IF(M23>0,Q23/M23,0) -> 0.27439433 | Q23: =Q20+Q21+Q22 -> 12205.334 | R23: =IF(M23>0,T23/M23,0) -> 0.079627751 | T23: =T20+T21+T22 -> 3541.922 | U23: =IF(M23>0,V23/M23,0) -> 0.2026713 | V23: =V20+V21+V22 -> 9015.022 | W23: =IF(M23>0,X23/M23,0) -> 0.51166523 | X23: =X20+X21+X22 -> 22759.381 | Y23: =IF(M23>0,Z23/M23,0) -> 0.38668173 | Z23: =Z20+Z21+Z22 -> 17199.99 | AA23: =IF(M23>0,AB23/M23,0) -> 0.0025031706 | AB23: =SUM(AB20:AB22) -> 111.34353 | AC23: =IF(M23>0,(AC20*M20+AC21*M21+AC22*M22)/M23,0) -> 0.0027168572 | AD23: =IF(K23>0,(K20*AD20+K21*AD21+K22*AD22)/K23,0) -> 0.00029 | AE23: =SUM(AE20:AE22) -> 12.89949 | AF23: =IF(K23>0,(K20*AF20+K21*AF21+K22*AF22)/K23,0) -> 0.21586506 | AG23: =SUM(AG20:AG22) -> 109.81456 | AH23: =IF(AND(AB23>0),((AB20*AH20+AB21*AH21+AB22*AH22)/AB23),0) -> 0.88533677 | AI23: =IF(AND(AC23>0,AL23>0,AD23>0),((AL23*(AC23-AD23))/(AC23*(AL23-AD23))),0) -> 0.89448184 | AJ23: =SUM(AJ20:AJ22) -> 555 | AK23: =IF(AJ23>0,(AK20*AJ20+AK21*AJ21+AK22*AJ22)/AJ23,0) -> 0.083403604 | AL23: =IF(K23>0,(AL20*K20+AL21*K21+AL22*K22)/K23,0) -> 0.21213195 | AM23: =IF(K23>0,(AM20*K20+AM21*K21+AM22*K22)/K23,0) -> 0.21613212 | AN23: =SUM(AN20:AN22) -> 107.94904 | AO23: =SUM(AO20:AO22) -> 109.95399 | AQ23: =SUM(AQ20:AQ22) -> 0 | AS23: =AR22 -> 2045.66 | AT23: =SUM(AT20:AT22) -> 0
A24: 6 | B24: 1 | C24: Георги Томов | D24: 5200 | E24: 0 | F24: 9029 | G24: 2.7 | H24: 4.8 | I24: 10313 | J24: 7.5 | K24: 16161 | L24: 0.084 | M24: =ROUND(K24*(1-L24),0) -> 14803 | N24: 0.552 | O24: =M24*N24 -> 8171.256 | P24: 0.326 | Q24: =M24*P24 -> 4825.778 | R24: 0.122 | S24: 0.2045 | T24: =M24*R24 -> 1805.966 | U24: 0.206 | V24: =M24*U24 -> 3049.418 | W24: 0.512 | X24: =M24*W24 -> 7579.136 | Y24: 0.39 | Z24: =Y24*M24 -> 5773.17 | AA24: 0.00255 | AB24: =M24*AA24 -> 37.74765 | AC24: =IF(M24>0,(AE24+AN24)/M24,0) -> 0.0027238133 | AD24: 0.00029 | AE24: =AD24*M24 -> 4.29287 | AF24: 0.2103 | AG24: =AJ24*(1-AK24)*AF24 -> 36.062034 | AH24: =IF(AND(AF24>0,AD24>0,AA24>0),((AA24-AD24)*AF24)/((AF24-AD24)*AA24),0) -> 0.88749835 | AI24: =IF(AND(AC24>0,AL24>0,AD24>0),((AL24*(AC24-AD24))/(AC24*(AL24-AD24))),0) -> 0.89476666 | AJ24: 187 | AK24: 0.083 | AL24: 0.2101 | AM24: 0.2098 | AN24: =AJ24*(1-AK24)*AL24 -> 36.027738 | AO24: =AJ24*(1-AK24)*AM24 -> 35.976294 | AP24: 1.55 | AQ24: 1004.3 | AR24: =AR22+AJ24-AQ24 -> 1228.36
B25: 2 | C25: Николинка Мутафова | D25: 19655 | E25: 2 | F25: 14497 | G25: 1.9 | H25: 5.4 | I25: 15896 | J25: 7.4 | K25: 16300 | L25: 0.091 | M25: =ROUND(K25*(1-L25),0) -> 14817 | N25: 0.726 | O25: =M25*N25 -> 10757.142 | P25: 0.192 | Q25: =M25*P25 -> 2844.864 | R25: 0.082 | S25: 0.2146 | T25: =M25*R25 -> 1214.994 | U25: 0.209 | V25: =M25*U25 -> 3096.753 | W25: 0.505 | X25: =M25*W25 -> 7482.585 | Y25: 0.38 | Z25: =Y25*M25 -> 5630.46 | AA25: 0.00239 | AB25: =M25*AA25 -> 35.41263 | AC25: =IF(M25>0,(AE25+AN25)/M25,0) -> 0.0025750729 | AD25: 0.00029 | AE25: =AD25*M25 -> 4.29693 | AF25: 0.2196 | AG25: =AJ25*(1-AK25)*AF25 -> 34.598419 | AH25: =IF(AND(AF25>0,AD25>0,AA25>0),((AA25-AD25)*AF25)/((AF25-AD25)*AA25),0) -> 0.87982297 | AI25: =IF(AND(AC25>0,AL25>0,AD25>0),((AL25*(AC25-AD25))/(AC25*(AL25-AD25))),0) -> 0.88858094 | AJ25: 172 | AK25: 0.084 | AL25: 0.2149 | AM25: 0.2261 | AN25: =AJ25*(1-AK25)*AL25 -> 33.857925 | AO25: =AJ25*(1-AK25)*AM25 -> 35.622507 | AP25: 1.6 | AR25: =AR24+AJ25-AQ25 -> 1400.36
B26: 3 | C26: Димитър Цончев | D26: 16170 | E26: 1 | F26: 14228 | G26: 1.6 | H26: 5.8 | I26: 16477 | J26: 7.5 | K26: 16309 | L26: 0.075 | M26: =ROUND(K26*(1-L26),0) -> 15086 | N26: 0.681 | O26: =M26*N26 -> 10273.566 | P26: 0.252 | Q26: =M26*P26 -> 3801.672 | R26: 0.067 | S26: 0.2131 | T26: =M26*R26 -> 1010.762 | U26: 0.211 | V26: =M26*U26 -> 3183.146 | W26: 0.504 | X26: =M26*W26 -> 7603.344 | Y26: 0.38 | Z26: =Y26*M26 -> 5732.68 | AA26: 0.00244 | AB26: =M26*AA26 -> 36.80984 | AC26: =IF(M26>0,(AE26+AN26)/M26,0) -> 0.0024103463 | AD26: 0.00029 | AE26: =AD26*M26 -> 4.37494 | AF26: 0.2233 | AG26: =AJ26*(1-AK26)*AF26 -> 32.931391 | AH26: =IF(AND(AF26>0,AD26>0,AA26>0),((AA26-AD26)*AF26)/((AF26-AD26)*AA26),0) -> 0.88229338 | AI26: =IF(AND(AC26>0,AL26>0,AD26>0),((AL26*(AC26-AD26))/(AC26*(AL26-AD26))),0) -> 0.88086307 | AJ26: 161 | AK26: 0.084 | AL26: 0.2169 | AM26: 0.2338 | AN26: =AJ26*(1-AK26)*AL26 -> 31.987544 | AO26: =AJ26*(1-AK26)*AM26 -> 34.479889 | AP26: 1.6 | AR26: =AR25+AJ26-AQ26 -> 1561.36
B27: Общо | D27: =SUM(D24:D26) -> 41025 | F27: =SUM(F24:F26) -> 37754 | I27: =SUM(I24:I26) -> 42686 | K27: =SUM(K24:K26) -> 48770 | L27: =IF(K27>0,(K24*L24+K25*L25+K26*L26)/K27,0) -> 0.083329895 | M27: =M24+M25+M26 -> 44706 | N27: =IF(M27>0,O27/M27,0) -> 0.65320011 | O27: =O24+O25+O26 -> 29201.964 | P27: =IF(M27>0,Q27/M27,0) -> 0.25661687 | Q27: =Q24+Q25+Q26 -> 11472.314 | R27: =IF(M27>0,T27/M27,0) -> 0.090183018 | T27: =T24+T25+T26 -> 4031.722 | U27: =IF(M27>0,V27/M27,0) -> 0.20868154 | V27: =V24+V25+V26 -> 9329.317 | W27: =IF(M27>0,X27/M27,0) -> 0.50698038 | X27: =X24+X25+X26 -> 22665.065 | Y27: =IF(M27>0,Z27/M27,0) -> 0.38331119 | Z27: =Z24+Z25+Z26 -> 17136.31 | AA27: =IF(M27>0,AB27/M27,0) -> 0.0024598515 | AB27: =SUM(AB24:AB26) -> 109.97012 | AC27: =IF(M27>0,(AC24*M24+AC25*M25+AC26*M26)/M27,0) -> 0.0025687368 | AD27: =IF(K27>0,(K24*AD24+K25*AD25+K26*AD26)/K27,0) -> 0.00029 | AE27: =SUM(AE24:AE26) -> 12.96474 | AF27: =IF(K27>0,(K24*AF24+K25*AF25+K26*AF26)/K27,0) -> 0.21775555 | AG27: =SUM(AG24:AG26) -> 103.59184 | AH27: =IF(AND(AB27>0),((AB24*AH24+AB25*AH25+AB26*AH26)/AB27),0) -> 0.88328448 | AI27: =IF(AND(AC27>0,AL27>0,AD27>0),((AL27*(AC27-AD27))/(AC27*(AL27-AD27))),0) -> 0.88830795 | AJ27: =SUM(AJ24:AJ26) -> 520 | AK27: =IF(AJ27>0,(AK24*AJ24+AK25*AJ25+AK26*AJ26)/AJ27,0) -> 0.083640385 | AL27: =IF(K27>0,(AL24*K24+AL25*K25+AL26*K26)/K27,0) -> 0.21397823 | AM27: =IF(K27>0,(AM24*K24+AM25*K25+AM26*K26)/K27,0) -> 0.22327357 | AN27: =SUM(AN24:AN26) -> 101.87321 | AO27: =SUM(AO24:AO26) -> 106.07869 | AQ27: =SUM(AQ24:AQ26) -> 1004.3 | AS27: =AR26 -> 1561.36 | AT27: =SUM(AT24:AT26) -> 0
A28: 7 | B28: 1 | C28: Иванка Копаранска | D28: 5400 | E28: 0 | F28: 13089 | G28: 1.3 | H28: 5 | I28: 14605 | J28: 7.7 | K28: 16230 | L28: 0.081 | M28: =ROUND(K28*(1-L28),0) -> 14915 | N28: 0.586 | O28: =M28*N28 -> 8740.19 | P28: 0.37 | Q28: =M28*P28 -> 5518.55 | R28: 0.044 | S28: 0.2125 | T28: =M28*R28 -> 656.26 | U28: 0.214 | V28: =M28*U28 -> 3191.81 | W28: 0.496 | X28: =M28*W28 -> 7397.84 | Y28: 0.38 | Z28: =Y28*M28 -> 5667.7 | AA28: 0.00256 | AB28: =M28*AA28 -> 38.1824 | AC28: =IF(M28>0,(AE28+AN28)/M28,0) -> 0.0028129761 | AD28: 0.0003 | AE28: =AD28*M28 -> 4.4745 | AF28: 0.2194 | AG28: =AJ28*(1-AK28)*AF28 -> 38.301536 | AH28: =IF(AND(AF28>0,AD28>0,AA28>0),((AA28-AD28)*AF28)/((AF28-AD28)*AA28),0) -> 0.88402128 | AI28: =IF(AND(AC28>0,AL28>0,AD28>0),((AL28*(AC28-AD28))/(AC28*(AL28-AD28))),0) -> 0.89460141 | AJ28: 191 | AK28: 0.086 | AL28: 0.2147 | AM28: 0.2199 | AN28: =AJ28*(1-AK28)*AL28 -> 37.481038 | AO28: =AJ28*(1-AK28)*AM28 -> 38.388823 | AP28: 1.68 | AQ28: 1001.52 | AR28: =AR26+AJ28-AQ28 -> 750.84
B29: 2 | C29: Николинка Мутафова | D29: 20335 | E29: 4 | F29: 14258 | G29: 3.1 | H29: 5.9 | I29: 15584 | J29: 7.8 | K29: 16415 | L29: 0.078 | M29: =ROUND(K29*(1-L29),0) -> 15135 | N29: 0.73 | O29: =M29*N29 -> 11048.55 | P29: 0.183 | Q29: =M29*P29 -> 2769.705 | R29: 0.087 | S29: 0.2155 | T29: =M29*R29 -> 1316.745 | U29: 0.218 | V29: =M29*U29 -> 3299.43 | W29: 0.491 | X29: =M29*W29 -> 7431.285 | Y29: 0.39 | Z29: =Y29*M29 -> 5902.65 | AA29: 0.00255 | AB29: =M29*AA29 -> 38.59425 | AC29: =IF(M29>0,(AE29+AN29)/M29,0) -> 0.0025084224 | AD29: 0.0003 | AE29: =AD29*M29 -> 4.5405 | AF29: 0.2189 | AG29: =AJ29*(1-AK29)*AF29 -> 33.686083 | AH29: =IF(AND(AF29>0,AD29>0,AA29>0),((AA29-AD29)*AF29)/((AF29-AD29)*AA29),0) -> 0.88356386 | AI29: =IF(AND(AC29>0,AL29>0,AD29>0),((AL29*(AC29-AD29))/(AC29*(AL29-AD29))),0) -> 0.88162063 | AJ29: 168 | AK29: 0.084 | AL29: 0.2172 | AM29: 0.2281 | AN29: =AJ29*(1-AK29)*AL29 -> 33.424474 | AO29: =AJ29*(1-AK29)*AM29 -> 35.101853 | AP29: 1.6 | AR29: =AR28+AJ29-AQ29 -> 918.84
B30: 3 | C30: Димитър Цончев | D30: 20965 | E30: 1 | F30: 15004 | G30: 3.5 | H30: 8.2 | I30: 17496 | J30: 7.5 | K30: 16322 | L30: 0.075 | M30: =ROUND(K30*(1-L30),0) -> 15098 | N30: 0.582 | O30: =M30*N30 -> 8787.036 | P30: 0.344 | Q30: =M30*P30 -> 5193.712 | R30: 0.074 | S30: 0.2187 | T30: =M30*R30 -> 1117.252 | U30: 0.218 | V30: =M30*U30 -> 3291.364 | W30: 0.504 | X30: =M30*W30 -> 7609.392 | Y30: 0.39 | Z30: =Y30*M30 -> 5888.22 | AA30: 0.00258 | AB30: =M30*AA30 -> 38.95284 | AC30: =IF(M30>0,(AE30+AN30)/M30,0) -> 0.0026855836 | AD30: 0.0003 | AE30: =AD30*M30 -> 4.5294 | AF30: 0.2163 | AG30: =AJ30*(1-AK30)*AF30 -> 37.36496 | AH30: =IF(AND(AF30>0,AD30>0,AA30>0),((AA30-AD30)*AF30)/((AF30-AD30)*AA30),0) -> 0.88494832 | AI30: =IF(AND(AC30>0,AL30>0,AD30>0),((AL30*(AC30-AD30))/(AC30*(AL30-AD30))),0) -> 0.8895724 | AJ30: 189 | AK30: 0.086 | AL30: 0.2085 | AM30: 0.2317 | AN30: =AJ30*(1-AK30)*AL30 -> 36.017541 | AO30: =AJ30*(1-AK30)*AM30 -> 40.025248 | AP30: 1.6 | AR30: =AR29+AJ30-AQ30 -> 1107.84
B31: Общо | D31: =SUM(D28:D30) -> 46700 | F31: =SUM(F28:F30) -> 42351 | I31: =SUM(I28:I30) -> 47685 | K31: =SUM(K28:K30) -> 48967 | L31: =IF(K31>0,(K28*L28+K29*L29+K30*L30)/K31,0) -> 0.077994364 | M31: =M28+M29+M30 -> 45148 | N31: =IF(M31>0,O31/M31,0) -> 0.63293559 | O31: =O28+O29+O30 -> 28575.776 | P31: =IF(M31>0,Q31/M31,0) -> 0.29861715 | Q31: =Q28+Q29+Q30 -> 13481.967 | R31: =IF(M31>0,T31/M31,0) -> 0.068447262 | T31: =T28+T29+T30 -> 3090.257 | U31: =IF(M31>0,V31/M31,0) -> 0.21667857 | V31: =V28+V29+V30 -> 9782.604 | W31: =IF(M31>0,X31/M31,0) -> 0.49699914 | X31: =X28+X29+X30 -> 22438.517 | Y31: =IF(M31>0,Z31/M31,0) -> 0.38669642 | Z31: =Z28+Z29+Z30 -> 17458.57 | AA31: =IF(M31>0,AB31/M31,0) -> 0.0025633359 | AB31: =SUM(AB28:AB30) -> 115.72949 | AC31: =IF(M31>0,(AC28*M28+AC29*M29+AC30*M30)/M31,0) -> 0.0026682788 | AD31: =IF(K31>0,(K28*AD28+K29*AD29+K30*AD30)/K31,0) -> 0.0003 | AE31: =SUM(AE28:AE30) -> 13.5444 | AF31: =IF(K31>0,(K28*AF28+K29*AF29+K30*AF30)/K31,0) -> 0.21819907 | AG31: =SUM(AG28:AG30) -> 109.35258 | AH31: =IF(AND(AB31>0),((AB28*AH28+AB29*AH29+AB30*AH30)/AB31),0) -> 0.88418076 | AI31: =IF(AND(AC31>0,AL31>0,AD31>0),((AL31*(AC31-AD31))/(AC31*(AL31-AD31))),0) -> 0.88881706 | AJ31: =SUM(AJ28:AJ30) -> 548 | AK31: =IF(AJ31>0,(AK28*AJ28+AK29*AJ29+AK30*AJ30)/AJ31,0) -> 0.085386861 | AL31: =IF(K31>0,(AL28*K28+AL29*K29+AL30*K30)/K31,0) -> 0.21347144 | AM31: =IF(L31>0,(AM28*K28+AM29*K29+AM30*K30)/K31,0) -> 0.2265821 | AN31: =SUM(AN28:AN30) -> 106.92305 | AO31: =SUM(AO28:AO30) -> 113.51592 | AQ31: =SUM(AQ28:AQ30) -> 1001.52 | AS31: =AR30 -> 1107.84 | AT31: =SUM(AT28:AT30) -> 0
A32: 8 | B32: 1 | C32: Иванка Копаранска | D32: 4597 | E32: 0 | F32: 9978 | G32: 4.7 | H32: 8 | I32: 11331 | J32: 8.7 | K32: 15098 | L32: 0.08 | M32: =ROUND(K32*(1-L32),0) -> 13890 | N32: 0.739 | O32: =M32*N32 -> 10264.71 | P32: 0.227 | Q32: =M32*P32 -> 3153.03 | R32: 0.034 | S32: 0.2075 | T32: =M32*R32 -> 472.26 | U32: 0.205 | V32: =M32*U32 -> 2847.45 | W32: 0.505 | X32: =M32*W32 -> 7014.45 | Y32: 0.37 | Z32: =Y32*M32 -> 5139.3 | AA32: 0.00264 | AB32: =M32*AA32 -> 36.6696 | AC32: =IF(M32>0,(AE32+AN32)/M32,0) -> 0.0026848865 | AD32: 0.00031 | AE32: =AD32*M32 -> 4.3059 | AF32: 0.2149 | AG32: =AJ32*(1-AK32)*AF32 -> 33.391162 | AH32: =IF(AND(AF32>0,AD32>0,AA32>0),((AA32-AD32)*AF32)/((AF32-AD32)*AA32),0) -> 0.88385074 | AI32: =IF(AND(AC32>0,AL32>0,AD32>0),((AL32*(AC32-AD32))/(AC32*(AL32-AD32))),0) -> 0.88583237 | AJ32: 170 | AK32: 0.086 | AL32: 0.2123 | AM32: 0.2174 | AN32: =AJ32*(1-AK32)*AL32 -> 32.987174 | AO32: =AJ32*(1-AK32)*AM32 -> 33.779612 | AP32: 1.6 | AQ32: 501.62 | AR32: =AR30+AJ32-AQ32+AS32 -> 764.8 | AS32: -11.42
B33: 2 | C33: Цвета Владова | D33: 22298 | E33: 1 | F33: 14760 | G33: 2.1 | H33: 4.7 | I33: 15659 | J33: 8 | K33: 15036 | L33: 0.09 | M33: =ROUND(K33*(1-L33),0) -> 13683 | N33: 0.694 | O33: =M33*N33 -> 9496.002 | P33: 0.218 | Q33: =M33*P33 -> 2982.894 | R33: 0.088 | S33: 0.205 | T33: =M33*R33 -> 1204.104 | U33: 0.209 | V33: =M33*U33 -> 2859.747 | W33: 0.506 | X33: =M33*W33 -> 6923.598 | Y33: 0.39 | Z33: =Y33*M33 -> 5336.37 | AA33: 0.00254 | AB33: =M33*AA33 -> 34.75482 | AC33: =IF(M33>0,(AE33+AN33)/M33,0) -> 0.0028754312 | AD33: 0.00031 | AE33: =AD33*M33 -> 4.24173 | AF33: 0.217 | AG33: =AJ33*(1-AK33)*AF33 -> 35.34713 | AH33: =IF(AND(AF33>0,AD33>0,AA33>0),((AA33-AD33)*AF33)/((AF33-AD33)*AA33),0) -> 0.87920877 | AI33: =IF(AND(AC33>0,AL33>0,AD33>0),((AL33*(AC33-AD33))/(AC33*(AL33-AD33))),0) -> 0.89347536 | AJ33: 179 | AK33: 0.09 | AL33: 0.2155 | AM33: 0.227 | AN33: =AJ33*(1-AK33)*AL33 -> 35.102795 | AO33: =AJ33*(1-AK33)*AM33 -> 36.97603 | AP33: 1.6 | AR33: =AR32+AJ33-AQ33 -> 943.8
B34: 3 | C34: Димитър Цончев | D34: 15855 | E34: 1 | F34: 14704 | G34: 0.7 | H34: 3.2 | I34: 16400 | J34: 7.7 | K34: 15000 | L34: 0.079 | M34: =ROUND(K34*(1-L34),0) -> 13815 | N34: 0.683 | O34: =M34*N34 -> 9435.645 | P34: 0.21 | Q34: =M34*P34 -> 2901.15 | R34: 0.107 | S34: 0.2044 | T34: =M34*R34 -> 1478.205 | U34: 0.21 | V34: =M34*U34 -> 2901.15 | W34: 0.507 | X34: =M34*W34 -> 7004.205 | Y34: 0.39 | Z34: =Y34*M34 -> 5387.85 | AA34: 0.00264 | AB34: =M34*AA34 -> 36.4716 | AC34: =IF(M34>0,(AE34+AN34)/M34,0) -> 0.0027607392 | AD34: 0.00031 | AE34: =AD34*M34 -> 4.28265 | AF34: 0.2142 | AG34: =AJ34*(1-AK34)*AF34 -> 34.41937 | AH34: =IF(AND(AF34>0,AD34>0,AA34>0),((AA34-AD34)*AF34)/((AF34-AD34)*AA34),0) -> 0.88385491 | AI34: =IF(AND(AC34>0,AL34>0,AD34>0),((AL34*(AC34-AD34))/(AC34*(AL34-AD34))),0) -> 0.88901923 | AJ34: 176 | AK34: 0.087 | AL34: 0.2107 | AM34: 0.2183 | AN34: =AJ34*(1-AK34)*AL34 -> 33.856962 | AO34: =AJ34*(1-AK34)*AM34 -> 35.07819 | AP34: 1.6 | AR34: =AR33+AJ34-AQ34 -> 1119.8
B35: Общо | D35: =SUM(D32:D34) -> 42750 | F35: =SUM(F32:F34) -> 39442 | I35: =SUM(I32:I34) -> 43390 | K35: =SUM(K32:K34) -> 45134 | L35: =IF(K35>0,(K32*L32+K33*L33+K34*L34)/K35,0) -> 0.082999069 | M35: =M32+M33+M34 -> 41388 | N35: =IF(M35>0,O35/M35,0) -> 0.70543049 | O35: =O32+O33+O34 -> 29196.357 | P35: =IF(M35>0,Q35/M35,0) -> 0.2183501 | Q35: =Q32+Q33+Q34 -> 9037.074 | R35: =IF(M35>0,T35/M35,0) -> 0.076219411 | T35: =T32+T33+T34 -> 3154.569 | U35: =IF(M35>0,V35/M35,0) -> 0.20799137 | V35: =V32+V33+V34 -> 8608.347 | W35: =IF(M35>0,X35/M35,0) -> 0.50599819 | X35: =X32+X33+X34 -> 20942.253 | Y35: =IF(M35>0,Z35/M35,0) -> 0.38328791 | Z35: =Z32+Z33+Z34 -> 15863.52 | AA35: =IF(M35>0,AB35/M35,0) -> 0.0026069397 | AB35: =SUM(AB32:AB34) -> 107.89602 | AC35: =IF(M35>0,(AC32*M32+AC33*M33+AC34*M34)/M35,0) -> 0.0027732002 | AD35: =IF(K35>0,(K32*AD32+K33*AD33+K34*AD34)/K35,0) -> 0.00031 | AE35: =SUM(AE32:AE34) -> 12.83028 | AF35: =IF(K35>0,(K32*AF32+K33*AF33+K34*AF34)/K35,0) -> 0.21536696 | AG35: =SUM(AG32:AG34) -> 103.15766 | AH35: =IF(AND(AB35>0),((AB32*AH32+AB33*AH33+AB34*AH34)/AB35),0) -> 0.88235691 | AI35: =IF(AND(AC35>0,AL35>0,AD35>0),((AL35*(AC35-AD35))/(AC35*(AL35-AD35))),0) -> 0.88951139 | AJ35: =SUM(AJ32:AJ34) -> 525 | AK35: =IF(AJ35>0,(AK32*AJ32+AK33*AJ33+AK34*AJ34)/AJ35,0) -> 0.087699048 | AL35: =IF(K35>0,(AL32*K32+AL33*K33+AL34*K34)/K35,0) -> 0.2128343 | AM35: =IF(L35>0,(AM32*K32+AM33*K33+AM34*K34)/K35,0) -> 0.22089727 | AN35: =SUM(AN32:AN34) -> 101.94693 | AO35: =SUM(AO32:AO34) -> 105.83383 | AQ35: =SUM(AQ32:AQ34) -> 501.62 | AS35: =AR34 -> 1119.8 | AT35: =SUM(AT32:AT34) -> 0
A36: 9 | B36: 1 | C36: Иванка Копаранска | D36: 3349 | E36: 0 | F36: 13259 | G36: 1.3 | H36: 4 | I36: 14984 | J36: 7.3 | K36: 14929 | L36: 0.081 | M36: =ROUND(K36*(1-L36),0) -> 13720 | N36: 0.595 | O36: =M36*N36 -> 8163.4 | P36: 0.242 | Q36: =M36*P36 -> 3320.24 | R36: 0.163 | S36: 0.2097 | T36: =M36*R36 -> 2236.36 | U36: 0.212 | V36: =M36*U36 -> 2908.64 | W36: 0.509 | X36: =M36*W36 -> 6983.48 | Y36: 0.4 | Z36: =Y36*M36 -> 5488 | AA36: 0.0027 | AB36: =M36*AA36 -> 37.044 | AC36: =IF(M36>0,(AE36+AN36)/M36,0) -> 0.0027284864 | AD36: 0.00033 | AE36: =AD36*M36 -> 4.5276 | AF36: 0.2128 | AG36: =AJ36*(1-AK36)*AF36 -> 32.374754 | AH36: =IF(AND(AF36>0,AD36>0,AA36>0),((AA36-AD36)*AF36)/((AF36-AD36)*AA36),0) -> 0.87914111 | AI36: =IF(AND(AC36>0,AL36>0,AD36>0),((AL36*(AC36-AD36))/(AC36*(AL36-AD36))),0) -> 0.88039701 | AJ36: 167 | AK36: 0.089 | AL36: 0.2163 | AM36: 0.2259 | AN36: =AJ36*(1-AK36)*AL36 -> 32.907233 | AO36: =AJ36*(1-AK36)*AM36 -> 34.367748 | AP36: 1.6 | AQ36: 501.78 | AR36: =AR34+AJ36-AQ36 -> 785.02
B37: 2 | C37: Цвета Владова | D37: 19106 | E37: 3 | F37: 13973 | G37: 1.7 | H37: 4.6 | I37: 15076 | J37: 7.3 | K37: 14863 | L37: 0.085 | M37: =ROUND(K37*(1-L37),0) -> 13600 | N37: 0.536 | O37: =M37*N37 -> 7289.6 | P37: 0.287 | Q37: =M37*P37 -> 3903.2 | R37: 0.177 | S37: 0.2099 | T37: =M37*R37 -> 2407.2 | U37: 0.205 | V37: =M37*U37 -> 2788 | W37: 0.484 | X37: =M37*W37 -> 6582.4 | Y37: 0.39 | Z37: =Y37*M37 -> 5304 | AA37: 0.00254 | AB37: =M37*AA37 -> 34.544 | AC37: =IF(M37>0,(AE37+AN37)/M37,0) -> 0.0030947346 | AD37: 0.00032 | AE37: =AD37*M37 -> 4.352 | AF37: 0.2114 | AG37: =AJ37*(1-AK37)*AF37 -> 38.408632 | AH37: =IF(AND(AF37>0,AD37>0,AA37>0),((AA37-AD37)*AF37)/((AF37-AD37)*AA37),0) -> 0.87534077 | AI37: =IF(AND(AC37>0,AL37>0,AD37>0),((AL37*(AC37-AD37))/(AC37*(AL37-AD37))),0) -> 0.89798207 | AJ37: 199 | AK37: 0.087 | AL37: 0.2077 | AM37: 0.2094 | AN37: =AJ37*(1-AK37)*AL37 -> 37.73639 | AO37: =AJ37*(1-AK37)*AM37 -> 38.045258 | AP37: 1.6 | AR37: =AR36+AJ37-AQ37 -> 984.02
B38: 3 | C38: Димитър Цончев | D38: 19695 | E38: 1 | F38: 14726 | G38: 1.6 | H38: 4.3 | I38: 16400 | J38: 6.7 | K38: 14948 | L38: 0.083 | M38: =ROUND(K38*(1-L38),0) -> 13707 | N38: 0.51 | O38: =M38*N38 -> 6990.57 | P38: 0.308 | Q38: =M38*P38 -> 4221.756 | R38: 0.182 | S38: 0.2123 | T38: =M38*R38 -> 2494.674 | U38: 0.223 | V38: =M38*U38 -> 3056.661 | W38: 0.499 | X38: =M38*W38 -> 6839.793 | Y38: 0.39 | Z38: =Y38*M38 -> 5345.73 | AA38: 0.00241 | AB38: =M38*AA38 -> 33.03387 | AC38: =IF(M38>0,(AE38+AN38)/M38,0) -> 0.0024994237 | AD38: 0.00032 | AE38: =AD38*M38 -> 4.38624 | AF38: 0.2124 | AG38: =AJ38*(1-AK38)*AF38 -> 31.027392 | AH38: =IF(AND(AF38>0,AD38>0,AA38>0),((AA38-AD38)*AF38)/((AF38-AD38)*AA38),0) -> 0.86852843 | AI38: =IF(AND(AC38>0,AL38>0,AD38>0),((AL38*(AC38-AD38))/(AC38*(AL38-AD38))),0) -> 0.87333708 | AJ38: 160 | AK38: 0.087 | AL38: 0.2045 | AM38: 0.206 | AN38: =AJ38*(1-AK38)*AL38 -> 29.87336 | AO38: =AJ38*(1-AK38)*AM38 -> 30.09248 | AP38: 1.6 | AR38: =AR37+AJ38-AQ38 -> 1144.02
B39: Общо | D39: =SUM(D36:D38) -> 42150 | F39: =SUM(F36:F38) -> 41958 | I39: =SUM(I36:I38) -> 46460 | K39: =SUM(K36:K38) -> 44740 | L39: =IF(K39>0,(K36*L36+K37*L37+K38*L38)/K39,0) -> 0.08299705 | M39: =M36+M37+M38 -> 41027 | N39: =IF(M39>0,O39/M39,0) -> 0.5470439 | O39: =O36+O37+O38 -> 22443.57 | P39: =IF(M39>0,Q39/M39,0) -> 0.27896741 | Q39: =Q36+Q37+Q38 -> 11445.196 | R39: =IF(M39>0,T39/M39,0) -> 0.17398869 | T39: =T36+T37+T38 -> 7138.234 | U39: =IF(M39>0,V39/M39,0) -> 0.21335464 | V39: =V36+V37+V38 -> 8753.301 | W39: =IF(M39>0,X39/M39,0) -> 0.4973718 | X39: =X36+X37+X38 -> 20405.673 | Y39: =IF(M39>0,Z39/M39,0) -> 0.39334414 | Z39: =Z36+Z37+Z38 -> 16137.73 | AA39: =IF(M39>0,AB39/M39,0) -> 0.0025500736 | AB39: =SUM(AB36:AB38) -> 104.62187 | AC39: =IF(M39>0,(AC36*M36+AC37*M37+AC38*M38)/M39,0) -> 0.0027733644 | AD39: =IF(K39>0,(K36*AD36+K37*AD37+K38*AD38)/K39,0) -> 0.00032333684 | AE39: =SUM(AE36:AE38) -> 13.26584 | AF39: =IF(K39>0,(K36*AF36+K37*AF37+K38*AF38)/K39,0) -> 0.21220127 | AG39: =SUM(AG36:AG38) -> 101.81078 | AH39: =IF(AND(AB39>0),((AB36*AH36+AB37*AH37+AB38*AH38)/AB39),0) -> 0.87453541 | AI39: =IF(AND(AC39>0,AL39>0,AD39>0),((AL39*(AC39-AD39))/(AC39*(AL39-AD39))),0) -> 0.88477905 | AJ39: =SUM(AJ36:AJ38) -> 526 | AK39: =IF(AJ39>0,(AK36*AJ36+AK37*AJ37+AK38*AJ38)/AJ39,0) -> 0.087634981 | AL39: =IF(K39>0,(AL36*K36+AL37*K37+AL38*K38)/K39,0) -> 0.20950053 | AM39: =IF(L39>0,(AM36*K36+AM37*K37+AM38*K38)/K39,0) -> 0.21376981 | AN39: =SUM(AN36:AN38) -> 100.51698 | AO39: =SUM(AO36:AO38) -> 102.50549 | AQ39: =SUM(AQ36:AQ38) -> 501.78 | AS39: =AR38 -> 1144.02 | AT39: =SUM(AT36:AT38) -> 0
A40: 10 | B40: 1 | C40: Николинка Мутафова | D40: 5564 | E40: 0 | F40: 9982 | G40: 1.8 | H40: 4.8 | I40: 11529 | J40: 7.8 | K40: 14993 | L40: 0.079 | M40: =ROUND(K40*(1-L40),0) -> 13809 | N40: 0.557 | O40: =M40*N40 -> 7691.613 | P40: 0.317 | Q40: =M40*P40 -> 4377.453 | R40: 0.126 | S40: 0.2114 | T40: =M40*R40 -> 1739.934 | U40: 0.204 | V40: =M40*U40 -> 2817.036 | W40: 0.517 | X40: =M40*W40 -> 7139.253 | Y40: 0.39 | Z40: =Y40*M40 -> 5385.51 | AA40: 0.00243 | AB40: =M40*AA40 -> 33.55587 | AC40: =IF(M40>0,(AE40+AN40)/M40,0) -> 0.0026179841 | AD40: 0.00032 | AE40: =AD40*M40 -> 4.41888 | AF40: 0.2147 | AG40: =AJ40*(1-AK40)*AF40 -> 33.250589 | AH40: =IF(AND(AF40>0,AD40>0,AA40>0),((AA40-AD40)*AF40)/((AF40-AD40)*AA40),0) -> 0.86960887 | AI40: =IF(AND(AC40>0,AL40>0,AD40>0),((AL40*(AC40-AD40))/(AC40*(AL40-AD40))),0) -> 0.87914154 | AJ40: 170 | AK40: 0.089 | AL40: 0.2049 | AM40: 0.2119 | AN40: =AJ40*(1-AK40)*AL40 -> 31.732863 | AO40: =AJ40*(1-AK40)*AM40 -> 32.816953 | AP40: 1.6 | AQ40: 501.98 | AR40: =AR38+AJ40-AQ40 -> 812.04
...

Sheet Февруари
A1: Дата | B1: Смяна | C1: Диспечер | D1: Подадена руда от МГТЛ за денонощието | E1: Състояние на склад №2 | F1: Натрошена руда от Цех ССТ | G1: Класа +15,0мм. | H1: Класа +12,5мм. | I1: Превозена руда до междинни бункери | J1: Състояние на междинни бункери | K1: Преработена руда в цех МФЦ | L1: Влага на преработената руда | M1: Суха преработена руда | N1: Грано диорити | P1: Дайки | R1: Шисти | S1: Показания на Гранулометър PSI500i руда, +0,20мм | U1: Смилане класа +0,20мм | W1: Смилане класа -0,08мм | Y1: Плътност на пулпа | AA1: Съдържание на мед в рудите по Химия | AB1: Метал мед в рудите по Химия | AC1: Съдържание на мед в рудите по Куриер | AD1: Метал мед в рудите по Куриер | AE1: Коригирана съдържание на мед в рудите | AF1: Съдържание на мед в отпадъка по Куриер | AG1: Метал мед в отпадъка по Куриер | AH1: Съдържание на мед в медния к-т Куриер | AI1: Метал мед в концентрата по Куриер | AJ1: Технологично извличане по Куриер | AK1: Товарно извличане | AL1: Добит меден концентрат | AM1: Влага на медния концентрат | AN1: Съдържание на мед в медния к-т (Брукер) | AO1: Съдържание на мед в медния к-т /химия-товарен/ | AP1: Метал мед в медния концентрат | AQ1: Метал мед в медния концентрат /химия/ | AR1: Литрово тегло в сгъстителя | AS1: Меден концентрат, автомобилна везна | AT1: Меден концентрат в склад | AU1: Меден концентрат в склад | AV1: Добит молибденов концентрат | AW1: Съдържание на Мо в молибденовия к-т | AX1: последни данни за съдържания в 8-ма пречистка | AZ1: последни данни за съдържания във 2-ра пречистка
D2: тона | E2: метра | F2: тона | G2: % | H2: % | I2: тона | K2: тона | L2: % | M2: тона | N2: % | P2: % | R2: % | U2: % | W2: % | Y2: % | AA2: % | AB2: % | AC2: % | AD2: % | AE2: % | AF2: % | AG2: тона | AH2: % | AI2: тона | AJ2: % | AK2: % | AL2: тона | AM2: % | AN2: % | AP2: тона | AR2: кг/литър | AS2: тон | AT2: тон | AU2: тон | AV2: кг. | AW2: % | AX2: Мо % | AY2: Cu % | AZ2: Мо % | BA2: Cu %
AT3: =Януари!AS127 -> 1589.56
A4: 1 | B4: 1 | C4: Димитър Цончев | D4: 16541 | E4: 0 | F4: 15138 | G4: 0.9 | H4: 3.3 | I4: 17610 | J4: 4 | K4: 16767 | L4: 0.083 | M4: =ROUND(K4*(1-L4),0) -> 15375 | N4: 0.538 | O4: =M4*N4 -> 8271.75 | P4: 0.37 | Q4: =M4*P4 -> 5688.75 | R4: 0.092 | S4: 0.2348 | T4: =M4*R4 -> 1414.5 | U4: 0.24 | V4: =M4*U4 -> 3690 | W4: 0.485 | X4: =M4*W4 -> 7456.875 | Y4: 0.39 | Z4: =Y4*M4 -> 5996.25 | AA4: 0.00263 | AB4: =M4*AA4 -> 40.43625 | AC4: 0.0025 | AD4: =M4*AC4 -> 38.4375 | AE4: =IF(M4>0,(AG4+AP4)/M4,0) -> 0.00032 | AF4: 0.00032 | AG4: =AF4*M4 -> 4.92 | AH4: 0.2126 | AI4: =AL4*(1-AM4)*AH4 -> 32.645155 | AJ4: =IF(AND(AH4>0,AF4>0,AC4>0),((AC4-AF4)*AH4)/((AH4-AF4)*AC4),0) -> 0.87331449 | AK4: =IF(AND(AE4>0,AN4>0,AF4>0),((AN4*(AE4-AF4))/(AE4*(AN4-AF4))),0) -> 0 | AL4: 168 | AM4: 0.086 | AO4: 0.2237 | AP4: =AL4*(1-AM4)*AN4 -> 0 | AQ4: =AL4*(1-AM4)*AO4 -> 34.349582 | AR4: 1.6 | AT4: =AT3+AL4-AS4 -> 1757.56
B5: 2 | C5: Иванка Копаранска | D5: 20564 | E5: 3 | F5: 16070 | G5: 1.3 | H5: 4.9 | I5: 17148 | J5: 3.3 | K5: 16852 | L5: 0.081 | M5: =ROUND(K5*(1-L5),0) -> 15487 | N5: 0.558 | O5: =M5*N5 -> 8641.746 | P5: 0.354 | Q5: =M5*P5 -> 5482.398 | R5: 0.088 | S5: 0.2409 | T5: =M5*R5 -> 1362.856 | U5: 0.241 | V5: =M5*U5 -> 3732.367 | W5: 0.484 | X5: =M5*W5 -> 7495.708 | Y5: 0.41 | Z5: =Y5*M5 -> 6349.67 | AA5: 0.00257 | AB5: =M5*AA5 -> 39.80159 | AC5: 0.00252 | AD5: =M5*AC5 -> 39.02724 | AE5: =IF(M5>0,(AG5+AP5)/M5,0) -> 0.00032 | AF5: 0.00032 | AG5: =AF5*M5 -> 4.95584 | AH5: 0.2074 | AI5: =AL5*(1-AM5)*AH5 -> 34.766047 | AJ5: =IF(AND(AH5>0,AF5>0,AC5>0),((AC5-AF5)*AH5)/((AH5-AF5)*AC5),0) -> 0.87436494 | AK5: =IF(AND(AE5>0,AN5>0,AF5>0),((AN5*(AE5-AF5))/(AE5*(AN5-AF5))),0) -> 0 | AL5: 183 | AM5: 0.084 | AO5: 0.2118 | AP5: =AL5*(1-AM5)*AN5 -> 0 | AQ5: =AL5*(1-AM5)*AO5 -> 35.50361 | AR5: 1.6 | AT5: =AT4+AL5-AS5 -> 1940.56
B6: 3 | C6: Георги Томов | D6: 17200 | E6: 3 | F6: 17570 | G6: 1.3 | H6: 5.2 | I6: 18717 | J6: 3 | K6: 16820 | L6: 0.083 | M6: =ROUND(K6*(1-L6),0) -> 15424 | N6: 0.751 | O6: =M6*N6 -> 11583.424 | P6: 0.202 | Q6: =M6*P6 -> 3115.648 | R6: 0.047 | S6: 0.2233 | T6: =M6*R6 -> 724.928 | U6: 0.242 | V6: =M6*U6 -> 3732.608 | W6: 0.496 | X6: =M6*W6 -> 7650.304 | Y6: 0.4 | Z6: =Y6*M6 -> 6169.6 | AA6: 0.00261 | AB6: =M6*AA6 -> 40.25664 | AC6: 0.00255 | AD6: =M6*AC6 -> 39.3312 | AE6: =IF(M6>0,(AG6+AP6)/M6,0) -> 0.00032 | AF6: 0.00032 | AG6: =AF6*M6 -> 4.93568 | AH6: 0.2069 | AI6: =AL6*(1-AM6)*AH6 -> 32.832547 | AJ6: =IF(AND(AH6>0,AF6>0,AC6>0),((AC6-AF6)*AH6)/((AH6-AF6)*AC6),0) -> 0.87586445 | AK6: =IF(AND(AE6>0,AN6>0,AF6>0),((AN6*(AE6-AF6))/(AE6*(AN6-AF6))),0) -> 0 | AL6: 174 | AM6: 0.088 | AO6: 0.2201 | AP6: =AL6*(1-AM6)*AN6 -> 0 | AQ6: =AL6*(1-AM6)*AO6 -> 34.927229 | AR6: 1.55 | AT6: =AT5+AL6-AS6 -> 2114.56
B7: Общо | D7: =SUM(D4:D6) -> 54305 | F7: =SUM(F4:F6) -> 48778 | I7: =SUM(I4:I6) -> 53475 | K7: =SUM(K4:K6) -> 50439 | L7: =IF(K7>0,(K4*L4+K5*L5+K6*L6)/K7,0) -> 0.082331787 | M7: =M4+M5+M6 -> 46286 | N7: =IF(M7>0,O7/M7,0) -> 0.6156704 | O7: =O4+O5+O6 -> 28496.92 | P7: =IF(M7>0,Q7/M7,0) -> 0.30866344 | Q7: =Q4+Q5+Q6 -> 14286.796 | R7: =IF(M7>0,T7/M7,0) -> 0.075666163 | T7: =T4+T5+T6 -> 3502.284 | U7: =IF(M7>0,V7/M7,0) -> 0.24100106 | V7: =V4+V5+V6 -> 11154.975 | W7: =IF(M7>0,X7/M7,0) -> 0.48833096 | X7: =X4+X5+X6 -> 22602.887 | Y7: =IF(M7>0,Z7/M7,0) -> 0.4000242 | Z7: =Z4+Z5+Z6 -> 18515.52 | AA7: =IF(M7>0,AB7/M7,0) -> 0.0026032597 | AB7: =SUM(AB4:AB6) -> 120.49448 | AC7: =IF(M7>0,AD7/M7,0) -> 0.0025233535 | AD7: =SUM(AD4:AD6) -> 116.79594 | AE7: =IF(M7>0,(AE4*M4+AE5*M5+AE6*M6)/M7,0) -> 0.00032 | AF7: =IF(K7>0,(K4*AF4+K5*AF5+K6*AF6)/K7,0) -> 0.00032 | AG7: =SUM(AG4:AG6) -> 14.81152 | AH7: =IF(K7>0,(K4*AH4+K5*AH5+K6*AH6)/K7,0) -> 0.20896185 | AI7: =SUM(AI4:AI6) -> 100.24375 | AJ7: =IF(AND(AD7>0),((AD4*AJ4+AD5*AJ5+AD6*AJ6)/AD7),0) -> 0.8745242 | AK7: =IF(AND(AE7>0,AN7>0,AF7>0),((AN7*(AE7-AF7))/(AE7*(AN7-AF7))),0) -> 0 | AL7: =SUM(AL4:AL6) -> 525 | AM7: =IF(AL7>0,(AM4*AL4+AM5*AL5+AM6*AL6)/AL7,0) -> 0.085965714 | AN7: =IF(K7>0,(AN4*K4+AN5*K5+AN6*K6)/K7,0) -> 0 | AO7: =IF(K7>0,(AO4*K4+AO5*K5+AO6*K6)/K7,0) -> 0.21852363 | AP7: =SUM(AP4:AP6) -> 0 | AQ7: =SUM(AQ4:AQ6) -> 104.78042 | AS7: =SUM(AS4:AS6) -> 0 | AU7: =AT6 -> 2114.56 | AV7: =SUM(AV4:AV6) -> 0
A8: 2 | B8: 1 | C8: Димитър Цончев | D8: 16331 | E8: 0 | F8: 15019 | G8: 0.7 | H8: 4.4 | I8: 16781 | J8: 3.8 | K8: 16801 | L8: 0.076 | M8: =ROUND(K8*(1-L8),0) -> 15524 | N8: 0.655 | O8: =M8*N8 -> 10168.22 | P8: 0.26 | Q8: =M8*P8 -> 4036.24 | R8: 0.085 | S8: 0.2365 | T8: =M8*R8 -> 1319.54 | U8: 0.232 | V8: =M8*U8 -> 3601.568 | W8: 0.492 | X8: =M8*W8 -> 7637.808 | Y8: 0.39 | Z8: =Y8*M8 -> 6054.36 | AA8: 0.00252 | AB8: =M8*AA8 -> 39.12048 | AC8: 0.00242 | AD8: =M8*AC8 -> 37.56808 | AE8: =IF(M8>0,(AG8+AP8)/M8,0) -> 0.00033 | AF8: 0.00033 | AG8: =AF8*M8 -> 5.12292 | AH8: 0.2035 | AI8: =AL8*(1-AM8)*AH8 -> 17.611908 | AJ8: =IF(AND(AH8>0,AF8>0,AC8>0),((AC8-AF8)*AH8)/((AH8-AF8)*AC8),0) -> 0.86503913 | AK8: =IF(AND(AE8>0,AN8>0,AF8>0),((AN8*(AE8-AF8))/(AE8*(AN8-AF8))),0) -> 0 | AL8: 95 | AM8: 0.089 | AO8: 0.2219 | AP8: =AL8*(1-AM8)*AN8 -> 0 | AQ8: =AL8*(1-AM8)*AO8 -> 19.204335 | AR8: 1.5 | AT8: =AT6+AL8-AS8 -> 2209.56
B9: 2 | C9: Иванка Копаранска | D9: 21629 | E9: 1 | F9: 14149 | G9: 0.8 | H9: 3.9 | I9: 15917 | J9: 3.1 | K9: 16347 | L9: 0.082 | M9: =ROUND(K9*(1-L9),0) -> 15007 | N9: 0.631 | O9: =M9*N9 -> 9469.417 | P9: 0.275 | Q9: =M9*P9 -> 4126.925 | R9: 0.094 | S9: 0.2267 | T9: =M9*R9 -> 1410.658 | U9: 0.238 | V9: =M9*U9 -> 3571.666 | W9: 0.497 | X9: =M9*W9 -> 7458.479 | Y9: 0.4 | Z9: =Y9*M9 -> 6002.8 | AA9: 0.00246 | AB9: =M9*AA9 -> 36.91722 | AC9: 0.0024 | AD9: =M9*AC9 -> 36.0168 | AE9: =IF(M9>0,(AG9+AP9)/M9,0) -> 0.00032 | AF9: 0.00032 | AG9: =AF9*M9 -> 4.80224 | AH9: 0.201 | AI9: =AL9*(1-AM9)*AH9 -> 32.593758 | AJ9: =IF(AND(AH9>0,AF9>0,AC9>0),((AC9-AF9)*AH9)/((AH9-AF9)*AC9),0) -> 0.86804863 | AK9: =IF(AND(AE9>0,AN9>0,AF9>0),((AN9*(AE9-AF9))/(AE9*(AN9-AF9))),0) -> 0 | AL9: 178 | AM9: 0.089 | AO9: 0.2047 | AP9: =AL9*(1-AM9)*AN9 -> 0 | AQ9: =AL9*(1-AM9)*AO9 -> 33.193743 | AR9: 1.6 | AT9: =AT8+AL9-AS9 -> 2387.56
B10: 3 | C10: Цвета Владова | D10: 12700 | E10: 1 | F10: 15465 | G10: 0.9 | H10: 4.5 | I10: 17334 | J10: 2.8 | K10: 16541 | L10: 0.079 | M10: =ROUND(K10*(1-L10),0) -> 15234 | N10: 0.675 | O10: =M10*N10 -> 10282.95 | P10: 0.291 | Q10: =M10*P10 -> 4433.094 | R10: 0.034 | S10: 0.2249 | T10: =M10*R10 -> 517.956 | U10: 0.233 | V10: =M10*U10 -> 3549.522 | W10: 0.48 | X10: =M10*W10 -> 7312.32 | Y10: 0.41 | Z10: =Y10*M10 -> 6245.94 | AA10: 0.00265 | AB10: =M10*AA10 -> 40.3701 | AC10: 0.00257 | AD10: =M10*AC10 -> 39.15138 | AE10: =IF(M10>0,(AG10+AP10)/M10,0) -> 0.00032 | AF10: 0.00032 | AG10: =AF10*M10 -> 4.87488 | AH10: 0.2014 | AI10: =AL10*(1-AM10)*AH10 -> 33.0584 | AJ10: =IF(AND(AH10>0,AF10>0,AC10>0),((AC10-AF10)*AH10)/((AH10-AF10)*AC10),0) -> 0.87687964 | AK10: =IF(AND(AE10>0,AN10>0,AF10>0),((AN10*(AE10-AF10))/(AE10*(AN10-AF10))),0) -> 0 | AL10: 179 | AM10: 0.083 | AO10: 0.2143 | AP10: =AL10*(1-AM10)*AN10 -> 0 | AQ10: =AL10*(1-AM10)*AO10 -> 35.175845 | AR10: 1.6 | AT10: =AT9+AL10-AS10 -> 2566.56
B11: Общо | D11: =SUM(D8:D10) -> 50660 | F11: =SUM(F8:F10) -> 44633 | I11: =SUM(I8:I10) -> 50032 | K11: =SUM(K8:K10) -> 49689 | L11: =IF(K11>0,(K8*L8+K9*L9+K10*L10)/K11,0) -> 0.07897259 | M11: =M8+M9+M10 -> 45765 | N11: =IF(M11>0,O11/M11,0) -> 0.65378755 | O11: =O8+O9+O10 -> 29920.587 | P11: =IF(M11>0,Q11/M11,0) -> 0.27523782 | Q11: =Q8+Q9+Q10 -> 12596.259 | R11: =IF(M11>0,T11/M11,0) -> 0.070974631 | T11: =T8+T9+T10 -> 3248.154 | U11: =IF(M11>0,V11/M11,0) -> 0.23430036 | V11: =V8+V9+V10 -> 10722.756 | W11: =IF(M11>0,X11/M11,0) -> 0.48964508 | X11: =X8+X9+X10 -> 22408.607 | Y11: =IF(M11>0,Z11/M11,0) -> 0.39993663 | Z11: =Z8+Z9+Z10 -> 18303.1 | AA11: =IF(M11>0,AB11/M11,0) -> 0.0025435988 | AB11: =SUM(AB8:AB10) -> 116.4078 | AC11: =IF(M11>0,AD11/M11,0) -> 0.0024633729 | AD11: =SUM(AD8:AD10) -> 112.73626 | AE11: =IF(M11>0,(AE8*M8+AE9*M9+AE10*M10)/M11,0) -> 0.00032339211 | AF11: =IF(K11>0,(K8*AF8+K9*AF9+K10*AF10)/K11,0) -> 0.00032338123 | AG11: =SUM(AG8:AG10) -> 14.80004 | AH11: =IF(K11>0,(K8*AH8+K9*AH9+K10*AH10)/K11,0) -> 0.20197846 | AI11: =SUM(AI8:AI10) -> 83.264066 | AJ11: =IF(AND(AD11>0),((AD8*AJ8+AD9*AJ9+AD10*AJ10)/AD11),0) -> 0.87011261 | AK11: =IF(AND(AE11>0,AN11>0,AF11>0),((AN11*(AE11-AF11))/(AE11*(AN11-AF11))),0) -> 0 | AL11: =SUM(AL8:AL10) -> 452 | AM11: =IF(AL11>0,(AM8*AL8+AM9*AL9+AM10*AL10)/AL11,0) -> 0.086623894 | AN11: =IF(K11>0,(AN8*K8+AN9*K9+AN10*K10)/K11,0) -> 0 | AO11: =IF(K11>0,(AO8*K8+AO9*K9+AO10*K10)/K11,0) -> 0.21371147 | AP11: =SUM(AP8:AP10) -> 0 | AQ11: =SUM(AQ8:AQ10) -> 87.573923 | AS11: =SUM(AS8:AS10) -> 0 | AU11: =AT10 -> 2566.56 | AV11: =SUM(AV8:AV10) -> 0
A12: 3 | B12: 1 | C12: Георги Томов | D12: 5930 | E12: 0 | F12: 8195 | G12: 0.6 | H12: 5 | I12: 9213 | J12: 5 | K12: 16450 | L12: 0.079 | M12: =ROUND(K12*(1-L12),0) -> 15150 | N12: 0.739 | O12: =M12*N12 -> 11195.85 | P12: 0.174 | Q12: =M12*P12 -> 2636.1 | R12: 0.087 | S12: 0.2276 | T12: =M12*R12 -> 1318.05 | U12: 0.232 | V12: =M12*U12 -> 3514.8 | W12: 0.491 | X12: =M12*W12 -> 7438.65 | Y12: 0.4 | Z12: =Y12*M12 -> 6060 | AA12: 0.00239 | AB12: =M12*AA12 -> 36.2085 | AC12: 0.00244 | AD12: =M12*AC12 -> 36.966 | AE12: =IF(M12>0,(AG12+AP12)/M12,0) -> 0.00032 | AF12: 0.00032 | AG12: =AF12*M12 -> 4.848 | AH12: 0.2006 | AI12: =AL12*(1-AM12)*AH12 -> 31.237432 | AJ12: =IF(AND(AH12>0,AF12>0,AC12>0),((AC12-AF12)*AH12)/((AH12-AF12)*AC12),0) -> 0.87024068 | AK12: =IF(AND(AE12>0,AN12>0,AF12>0),((AN12*(AE12-AF12))/(AE12*(AN12-AF12))),0) -> 0 | AL12: 170 | AM12: 0.084 | AO12: 0.225 | AP12: =AL12*(1-AM12)*AN12 -> 0 | AQ12: =AL12*(1-AM12)*AO12 -> 35.037 | AR12: 1.55 | AS12: 1103.38 | AT12: =AT10+AL12-AS12 -> 1633.18
B13: 2 | C13: Иванка Копаранска | D13: 19670 | E13: 1 | F13: 14185 | G13: 1.9 | H13: 6.2 | I13: 15917 | J13: 5.1 | K13: 16416 | L13: 0.078 | M13: =ROUND(K13*(1-L13),0) -> 15136 | N13: 0.685 | O13: =M13*N13 -> 10368.16 | P13: 0.251 | Q13: =M13*P13 -> 3799.136 | R13: 0.064 | S13: 0.2293 | T13: =M13*R13 -> 968.704 | U13: 0.235 | V13: =M13*U13 -> 3556.96 | W13: 0.493 | X13: =M13*W13 -> 7462.048 | Y13: 0.4 | Z13: =Y13*M13 -> 6054.4 | AA13: 0.00258 | AB13: =M13*AA13 -> 39.05088 | AC13: 0.00244 | AD13: =M13*AC13 -> 36.93184 | AE13: =IF(M13>0,(AG13+AP13)/M13,0) -> 0.0003 | AF13: 0.0003 | AG13: =AF13*M13 -> 4.5408 | AH13: 0.1982 | AI13: =AL13*(1-AM13)*AH13 -> 31.11304 | AJ13: =IF(AND(AH13>0,AF13>0,AC13>0),((AC13-AF13)*AH13)/((AH13-AF13)*AC13),0) -> 0.87837871 | AK13: =IF(AND(AE13>0,AN13>0,AF13>0),((AN13*(AE13-AF13))/(AE13*(AN13-AF13))),0) -> 0 | AL13: 171 | AM13: 0.082 | AO13: 0.2122 | AP13: =AL13*(1-AM13)*AN13 -> 0 | AQ13: =AL13*(1-AM13)*AO13 -> 33.310732 | AR13: 1.6 | AT13: =AT12+AL13-AS13 -> 1804.18
B14: 3 | C14: Цвета Владова | D14: 13600 | E14: 0 | F14: 13578 | G14: 1.6 | H14: 4.9 | I14: 15403 | J14: 4.3 | K14: 15201 | L14: 0.083 | M14: =ROUND(K14*(1-L14),0) -> 13939 | N14: 0.666 | O14: =M14*N14 -> 9283.374 | P14: 0.253 | Q14: =M14*P14 -> 3526.567 | R14: 0.081 | S14: 0.2188 | T14: =M14*R14 -> 1129.059 | U14: 0.229 | V14: =M14*U14 -> 3192.031 | W14: 0.49 | X14: =M14*W14 -> 6830.11 | Y14: 0.42 | Z14: =Y14*M14 -> 5854.38 | AA14: 0.00274 | AB14: =M14*AA14 -> 38.19286 | AC14: 0.00245 | AD14: =M14*AC14 -> 34.15055 | AE14: =IF(M14>0,(AG14+AP14)/M14,0) -> 0.0003 | AF14: 0.0003 | AG14: =AF14*M14 -> 4.1817 | AH14: 0.2043 | AI14: =AL14*(1-AM14)*AH14 -> 32.516388 | AJ14: =IF(AND(AH14>0,AF14>0,AC14>0),((AC14-AF14)*AH14)/((AH14-AF14)*AC14),0) -> 0.87884154 | AK14: =IF(AND(AE14>0,AN14>0,AF14>0),((AN14*(AE14-AF14))/(AE14*(AN14-AF14))),0) -> 0 | AL14: 173 | AM14: 0.08 | AO14: 0.2167 | AP14: =AL14*(1-AM14)*AN14 -> 0 | AQ14: =AL14*(1-AM14)*AO14 -> 34.489972 | AR14: 1.55 | AT14: =AT13+AL14-AS14 -> 1977.18
B15: Общо | D15: =SUM(D12:D14) -> 39200 | F15: =SUM(F12:F14) -> 35958 | I15: =SUM(I12:I14) -> 40533 | K15: =SUM(K12:K14) -> 48067 | L15: =IF(K15>0,(K12*L12+K13*L13+K14*L14)/K15,0) -> 0.079923461 | M15: =M12+M13+M14 -> 44225 | N15: =IF(M15>0,O15/M15,0) -> 0.6975101 | O15: =O12+O13+O14 -> 30847.384 | P15: =IF(M15>0,Q15/M15,0) -> 0.22525275 | Q15: =Q12+Q13+Q14 -> 9961.803 | R15: =IF(M15>0,T15/M15,0) -> 0.077237151 | T15: =T12+T13+T14 -> 3415.813 | U15: =IF(M15>0,V15/M15,0) -> 0.2320812 | V15: =V12+V13+V14 -> 10263.791 | W15: =IF(M15>0,X15/M15,0) -> 0.49136932 | X15: =X12+X13+X14 -> 21730.808 | Y15: =IF(M15>0,Z15/M15,0) -> 0.40630367 | Z15: =Z12+Z13+Z14 -> 17968.78 | AA15: =IF(M15>0,AB15/M15,0) -> 0.0025653418 | AB15: =SUM(AB12:AB14) -> 113.45224 | AC15: =IF(M15>0,AD15/M15,0) -> 0.0024431518 | AD15: =SUM(AD12:AD14) -> 108.04839 | AE15: =IF(M15>0,(AE12*M12+AE13*M13+AE14*M14)/M15,0) -> 0.00030685133 | AF15: =IF(K15>0,(K12*AF12+K13*AF13+K14*AF14)/K15,0) -> 0.00030684461 | AG15: =SUM(AG12:AG14) -> 13.5705 | AH15: =IF(K15>0,(K12*AH12+K13*AH13+K14*AH14)/K15,0) -> 0.20095045 | AI15: =SUM(AI12:AI14) -> 94.86686 | AJ15: =IF(AND(AD15>0),((AD12*AJ12+AD13*AJ13+AD14*AJ14)/AD15),0) -> 0.87574078 | AK15: =IF(AND(AE15>0,AN15>0,AF15>0),((AN15*(AE15-AF15))/(AE15*(AN15-AF15))),0) -> 0 | AL15: =SUM(AL12:AL14) -> 514 | AM15: =IF(AL15>0,(AM12*AL12+AM13*AL13+AM14*AL14)/AL15,0) -> 0.081988327 | AN15: =IF(K15>0,(AN12*K12+AN13*K13+AN14*K14)/K15,0) -> 0 | AO15: =IF(K15>0,(AO12*K12+AO13*K13+AO14*K14)/K15,0) -> 0.21800366 | AP15: =SUM(AP12:AP14) -> 0 | AQ15: =SUM(AQ12:AQ14) -> 102.8377 | AS15: =SUM(AS12:AS14) -> 1103.38 | AU15: =AT14 -> 1977.18 | AV15: =SUM(AV12:AV14) -> 0
